Workbook

Sheet Cover
B3: APPLE INC.
B6: Equity Research & Financial Projection Model
B10: Ticker: | C10: AAPL (NASDAQ)
B11: Sector: | C11: Technology
B12: Sub-Industry: | C12: Technology Hardware & Equipment
B13: Model Version: | C13: v1.0
B14: Prepared By: | C14: Equity Research
B15: Date: | C15: 14 March 2026
B16: Fiscal Year End: | C16: Last Saturday of September
B17: Currency: | C17: USD ($millions)
B18: Hist. Period: | C18: FY2021 – FY2025
B19: Proj. Period: | C19: FY2026E – FY2030E
B20: DISCLAIMER: This financial model is prepared for analytical and informational purposes only. It does not constitute investment advice. Projections are based on publicly available data and reasonable assumptions; actual results may differ materially.
B25: MODEL STRUCTURE
B26: =HYPERLINK("#'Assumptions & Drivers'!A5","Assumptions & Drivers") -> Assumptions & Drivers | C26: =HYPERLINK("#'Assumptions & Drivers'!B65","READ ME") -> READ ME
B27: =HYPERLINK("#'Income Statement'!A5","Income Statement") -> Income Statement | C27: Historical P&L (FY2021–FY2025) with 5 year forward projections
B28: =HYPERLINK("#'Cash Flow Statement'!A5","Cash Flow Statement") -> Cash Flow Statement | C28: Historical cash flows (FY2021–FY2025) with 5 year forward projections
B29: =HYPERLINK("#'Balance Sheet'!A5","Balance Sheet") -> Balance Sheet | C29: Historical balance sheet (FY2021–FY2025) with 5 year forward projections
B30: =HYPERLINK("#'Financial Summary'!A5","Financial Summary") -> Financial Summary | C30: Includes key ratios for comparable analysis
B31: =HYPERLINK("#'DCF'!A5","DCF") -> DCF | C31: Implied Share Price
B32: =HYPERLINK("#'Sensitivity Analysis'!A5","Sensitivity Analysis") -> Sensitivity Analysis | C32: Currently based on Implied Share Price and Year 5 EBITDA
B33: =HYPERLINK("#'Scenario Analysis'!A5","Scenario Analysis") -> Scenario Analysis | C33: Figure projections for potential scenarios

Sheet Assumptions & Drivers
B1: ASSUMPTIONS & DRIVERS
B2: Model Version 1.0 | All projections in USD ($millions) | Blue = editable input
B4: Assumption / Driver | C4: Notes / Source | D4: FY2025A | E4: FY2026E | F4: FY2027E | G4: FY2028E | H4: FY2029E | I4: FY2030E
B6: 1. REVENUE GROWTH ASSUMPTIONS | M6: Metric Tweaks | N6: CHECK
B7: Product Revenue Growth (YoY %) | C7: iPhone, Mac, iPad, Wearables | D7: ='Income Statement'!G7/'Income Statement'!F7-1 -> 0.04116107 | E7: 0.04116107 | F7: 0.04116107 | G7: 0.04116107 | H7: 0.04116107 | I7: 0.04116107 | M7: =HYPERLINK("#D44","Theoretical WACC?") -> Theoretical WACC? | N7: =_xlfn.ISFORMULA(D45) -> TRUE
B8: Services Revenue Growth (YoY %) | C8: App Store, AppleCare, iCloud, etc. | D8: ='Income Statement'!G8/'Income Statement'!F8-1 -> 0.13506431 | E8: 0.13506431 | F8: 0.13506431 | G8: 0.13506431 | H8: 0.13506431 | I8: 0.13506431 | M8: =HYPERLINK("#E7","Normal Revenue Growth?") -> Normal Revenue Growth? | N8: =AND(ABS(E7-D7)/D7<0.1,ABS(E8-D8)/D8<0.1) -> TRUE
B10: 2. MARGIN ASSUMPTIONS | M10: =HYPERLINK("#D52","Normal Terminal Growth?") -> Normal Terminal Growth? | N10: =D53 -> 0.025
B11: Product Gross Margin (%) | C11: Hardware margin; modest expansion from mix | D11: =('Income Statement'!G7-'Income Statement'!G14)/'Income Statement'!G7 -> 0.3677065 | E11: 0.367 | F11: 0.372 | G11: 0.377 | H11: 0.37 | I11: 0.37 | M11: =HYPERLINK("#D53","Normal Exit Multiple?") -> Normal Exit Multiple? | N11: =D54 -> 15
B12: Services Gross Margin (%) | C12: High-margin software/services segment | D12: =('Income Statement'!G8-'Income Statement'!G15)/'Income Statement'!G8 -> 0.75408124 | E12: 0.757 | F12: 0.762 | G12: 0.767 | H12: 0.75 | I12: 0.75
B13: R&D as % of Revenue | C13: Sustained investment in silicon, AI, XR | D13: ='Income Statement'!G25/'Income Statement'!G10 -> 0.083020754 | E13: 0.084 | F13: 0.083 | G13: 0.082 | H13: 0.081 | I13: 0.08
B14: SG&A as % of Revenue | C14: Operating leverage on fixed cost base | D14: ='Income Statement'!G28/'Income Statement'!G10 -> 0.066322889 | E14: 0.065 | F14: 0.064 | G14: 0.063 | H14: 0.062 | I14: 0.061
B16: 3. DEPRECIATION, AMORTIZATION & CAPEX
B17: D&A as % of Revenue | C17: Stable asset base; modest PP&E growth | D17: ='Cash Flow Statement'!G9/'Income Statement'!G10 -> 0.028109313 | E17: 0.028 | F17: 0.028 | G17: 0.027 | H17: 0.027 | I17: 0.027
B18: CapEx Intensity (CapEx / Revenue) | C18: Data centre, retail, R&D facilities | D18: =-'Cash Flow Statement'!G25/'Income Statement'!G10 -> 0.030553079 | E18: 0.031 | F18: 0.03 | G18: 0.029 | H18: 0.029 | I18: 0.028
B19: SBC as % of Revenue | C19: Sustains talent via RSU/option programmes | D19: ='Cash Flow Statement'!G10/'Income Statement'!G10 -> 0.030908711 | E19: 0.031 | F19: 0.031 | G19: 0.03 | H19: 0.03 | I19: 0.029
B21: 4. WORKING CAPITAL DAYS
B22: Days Sales Outstanding (DSO) | C22: AR / Revenue × 365 | D22: ='Balance Sheet'!G10/'Income Statement'!G10*365 -> 34.886991
B23: Days Inventory Outstanding (DIO) | C23: Inventory / COGS × 365 | D23: ='Balance Sheet'!G12/'Income Statement'!G18*365 -> 9.4454652
B24: Days Payable Outstanding (DPO) | C24: AP / COGS × 365 | D24: ='Balance Sheet'!G31/'Income Statement'!G18*365 -> 115.40052
B26: 5. TAX RATE & INTEREST
B27: Effective Tax Rate (%) | C27: Blended rate; elevated FY24 normalises | D27: ='Income Statement'!G47/'Income Statement'!G44 -> 0.15610002 | E27: 0.21 | F27: 0.21 | G27: 0.21 | H27: 0.21 | I27: 0.21
B28: Interest Income Rate (% on avg. cash) | C28: Short-term yields modestly declining | E28: 0.042 | F28: 0.04 | G28: 0.038 | H28: 0.037 | I28: 0.036
B29: Interest Expense Rate (% on avg. debt) | C29: Average coupon on long-term debt | E29: 0.03 | F29: 0.029 | G29: 0.028 | H29: 0.028 | I29: 0.027
B31: 6. CAPITAL RETURN ASSUMPTIONS
B32: Annual Share Buyback ($mm) | C32: Assumes sustained ~$90bn programme | E32: 90000 | F32: 85000 | G32: 80000 | H32: 75000 | I32: 70000
B33: Annual Dividend per Share ($) | C33: ~5% annual growth in DPS | D33: 1.0277448 | E33: =MID($C$33,2,1)/100+D33 -> 1.0777448 | F33: =MID($C$33,2,1)/100+E33 -> 1.1277448 | G33: =MID($C$33,2,1)/100+F33 -> 1.1777448 | H33: =MID($C$33,2,1)/100+G33 -> 1.2277448 | I33: =MID($C$33,2,1)/100+H33 -> 1.2777448
B35: 7. WACC COMPONENTS (for reference)
B36: Risk-Free Rate (10Y UST Yield, %) | C36: 4.30% | D36: 0.043
B37: Equity Risk Premium (%) | C37: Damodaran Jan-2025 | D37: 0.048
B38: Beta (5Y Monthly, vs. S&P 500) | C38: Bloomberg | D38: 1.25
B39: Cost of Equity – CAPM (%) | C39: Rf + β × ERP (CAPM) | D39: =D36+D38*D37 -> 0.103 | E39: * Suggested 9%
B40: Pre-Tax Cost of Debt (%) | C40: Weighted avg. coupon | D40: 0.03
B41: Marginal Tax Rate (%) | C41: Federal + state blended | D41: 0.21
B42: After-Tax Cost of Debt (%) | C42: kd × (1 – tax rate) | D42: =D40*(1-D41) -> 0.0237 | E42: * Suggested 5%
B43: Equity Weight (%) | C43: Market cap / EV | D43: 0.94
B44: Debt Weight (%) | C44: Net debt / EV | D44: 0.06
B45: WACC (%) | C45: ke×We + kd×Wd×(1-t) | D45: =D39*D43+D42*D44 -> 0.098242 | E45: *Suggested 8% for APPL's massive cash moat, low bankruptcy risk and consistent stock buybacks
B47: 8. DILUTED SHARE COUNT
B48: Beginning Diluted Shares | C48: End of prior year count | D48: ='Income Statement'!G53 -> 15004697000
B49: Net Shares Retired via Buybacks | C49: Assumed avg. price for retirement | E49: 550000000 | F49: 500000000 | G49: 460000000 | H49: 420000000 | I49: 390000000
...

Sheet Raw (Income Statement)
A1: RAW | I1: ADJUSTED
A2: AAPL_income-statement_Annual_As_Originally_Reported | B2: 2021 | C2: 2022 | D2: 2023 | E2: 2024 | F2: 2025 | G2: TTM | I2: =A2 -> AAPL_income-statement_Annual_As_Originally_Reported | J2: =B2 -> 2021 | K2: =C2 -> 2022 | L2: =D2 -> 2023 | M2: =E2 -> 2024 | N2: =F2 -> 2025 | O2: =G2 -> TTM
A3: Gross Profit | B3: 152836000000 | C3: 170782000000 | D3: 169148000000 | E3: 180683000000 | F3: 195201000000 | G3: 206157000000 | I3: =A3 -> Gross Profit | J3: =B3 -> 152836000000 | K3: =C3 -> 170782000000 | L3: =D3 -> 169148000000 | M3: =E3 -> 180683000000 | N3: =F3 -> 195201000000 | O3: =G3 -> 206157000000
A4: Total Revenue | B4: 365817000000 | C4: 394328000000 | D4: 383285000000 | E4: 391035000000 | F4: 416161000000 | G4: 435617000000 | I4: =A4 -> Total Revenue | J4: =B4 -> 365817000000 | K4: =C4 -> 394328000000 | L4: =D4 -> 383285000000 | M4: =E4 -> 391035000000 | N4: =F4 -> 416161000000 | O4: =G4 -> 435617000000
A5: Business Revenue | B5: 365817000000 | C5: 394328000000 | D5: 383285000000 | E5: 391035000000 | F5: 416161000000 | G5: 435617000000 | I5: -Products | J5: 297392000000 | K5: 316199000000 | L5: 298085000000 | M5: 294866000000 | N5: 307003000000
A6: Cost of Revenue | B6: -212981000000 | C6: -223546000000 | D6: -214137000000 | E6: -210352000000 | F6: -220960000000 | G6: -229460000000 | I6: -Services | J6: 68425000000 | K6: 78129000000 | L6: 85200000000 | M6: 96169000000 | N6: 109158000000
A7: Cost of Goods and Services | B7: -212981000000 | C7: -223546000000 | D7: -214137000000 | E7: -210352000000 | F7: -220960000000 | G7: -229460000000 | I7: Reconcialiation Check | J7: =ABS(SUM(J5:J6))=ABS(J4) -> TRUE | K7: =ABS(SUM(K5:K6))=ABS(K4) -> TRUE | L7: =ABS(SUM(L5:L6))=ABS(L4) -> TRUE | M7: =ABS(SUM(M5:M6))=ABS(M4) -> TRUE | N7: =ABS(SUM(N5:N6))=ABS(N4) -> TRUE | P7: =AND(J7:O7) -> TRUE
A8: Operating Income/Expenses | B8: -43887000000 | C8: -51345000000 | D8: -54847000000 | E8: -57467000000 | F8: -62151000000 | G8: -65087000000 | I8: =A5 -> Business Revenue | J8: =B5 -> 365817000000 | K8: =C5 -> 394328000000 | L8: =D5 -> 383285000000 | M8: =E5 -> 391035000000 | N8: =F5 -> 416161000000 | O8: =G5 -> 435617000000
A9: Selling, General and Administrative Expenses | B9: -21973000000 | C9: -25094000000 | D9: -24932000000 | E9: -26097000000 | F9: -27601000000 | G9: -27918000000 | I9: =A6 -> Cost of Revenue | J9: =B6 -> -212981000000 | K9: =C6 -> -223546000000 | L9: =D6 -> -214137000000 | M9: =E6 -> -210352000000 | N9: =F6 -> -220960000000 | O9: =G6 -> -229460000000
A10: Research and Development Expenses | B10: -21914000000 | C10: -26251000000 | D10: -29915000000 | E10: -31370000000 | F10: -34550000000 | G10: -37169000000 | I10: =A7 -> Cost of Goods and Services | J10: =B7 -> -212981000000 | K10: =C7 -> -223546000000 | L10: =D7 -> -214137000000 | M10: =E7 -> -210352000000 | N10: =F7 -> -220960000000
A11: Total Operating Profit/Loss | B11: 108949000000 | C11: 119437000000 | D11: 114301000000 | E11: 123216000000 | F11: 133050000000 | G11: 141070000000 | I11: -Products | J11: 192266000000 | K11: 201471000000 | L11: 189282000000 | M11: 185233000000 | N11: 194116000000
A12: Non-Operating Income/Expense, Total | B12: 258000000 | C12: -334000000 | D12: -565000000 | E12: 269000000 | F12: -321000000 | G12: 77000000 | I12: -Services | J12: 20715000000 | K12: 22075000000 | L12: 24855000000 | M12: 25119000000 | N12: 26844000000
A13: Other Income/Expense, Non-Operating | B13: 60000000 | C13: -228000000 | D13: -382000000 | E13: 269000000 | F13: -321000000 | G13: 77000000 | I13: Reconcialiation Check | J13: =ABS(SUM(J11:J12))=ABS(J10) -> TRUE | K13: =ABS(SUM(K11:K12))=ABS(K10) -> TRUE | L13: =ABS(SUM(L11:L12))=ABS(L10) -> TRUE | M13: =ABS(SUM(M11:M12))=ABS(M10) -> TRUE | N13: =ABS(SUM(N11:N12))=ABS(N10) -> TRUE | P13: =AND(J13:O13) -> TRUE
A14: Total Net Finance Income/Expense | B14: 198000000 | C14: -106000000 | D14: -183000000 | I14: =A8 -> Operating Income/Expenses | J14: =B8 -> -43887000000 | K14: =C8 -> -51345000000 | L14: =D8 -> -54847000000 | M14: =E8 -> -57467000000 | N14: =F8 -> -62151000000 | O14: =G8 -> -65087000000
A15: Net Interest Income/Expense | B15: 198000000 | C15: -106000000 | D15: -183000000 | I15: =A9 -> Selling, General and Administrative Expenses | J15: =B9 -> -21973000000 | K15: =C9 -> -25094000000 | L15: =D9 -> -24932000000 | M15: =E9 -> -26097000000 | N15: =F9 -> -27601000000 | O15: =G9 -> -27918000000
A16: Interest Expense Net of Capitalized Interest | B16: -2645000000 | C16: -2931000000 | D16: -3933000000 | I16: =A10 -> Research and Development Expenses | J16: =B10 -> -21914000000 | K16: =C10 -> -26251000000 | L16: =D10 -> -29915000000 | M16: =E10 -> -31370000000 | N16: =F10 -> -34550000000 | O16: =G10 -> -37169000000
A17: Interest Income | B17: 2843000000 | C17: 2825000000 | D17: 3750000000 | I17: =A11 -> Total Operating Profit/Loss | J17: =B11 -> 108949000000 | K17: =C11 -> 119437000000 | L17: =D11 -> 114301000000 | M17: =E11 -> 123216000000 | N17: =F11 -> 133050000000 | O17: =G11 -> 141070000000
A18: Pretax Income | B18: 109207000000 | C18: 119103000000 | D18: 113736000000 | E18: 123485000000 | F18: 132729000000 | G18: 141147000000 | I18: =A12 -> Non-Operating Income/Expense, Total | J18: =B12 -> 258000000 | K18: =C12 -> -334000000 | L18: =D12 -> -565000000 | M18: =E12 -> 269000000 | N18: =F12 -> -321000000 | O18: =G12 -> 77000000
A19: Provision for Income Tax | B19: -14527000000 | C19: -19300000000 | D19: -16741000000 | E19: -29749000000 | F19: -20719000000 | G19: -23370000000 | I19: =A13 -> Other Income/Expense, Non-Operating | J19: =B13 -> 60000000 | K19: =C13 -> -228000000 | L19: =D13 -> -382000000 | M19: =E13 -> 269000000 | N19: =F13 -> -321000000 | O19: =G13 -> 77000000
A20: Net Income before Extraordinary Items and Discontinued Operations | B20: 94680000000 | C20: 99803000000 | D20: 96995000000 | E20: 93736000000 | F20: 112010000000 | G20: 117777000000 | I20: =A14 -> Total Net Finance Income/Expense | J20: =B14 -> 198000000 | K20: =C14 -> -106000000 | L20: =D14 -> -183000000 | M20: =E14 | N20: =F14 | O20: =G14
A21: Net Income after Extraordinary Items and Discontinued Operations | B21: 94680000000 | C21: 99803000000 | D21: 96995000000 | E21: 93736000000 | F21: 112010000000 | G21: 117777000000 | I21: =A15 -> Net Interest Income/Expense | J21: =B15 -> 198000000 | K21: =C15 -> -106000000 | L21: =D15 -> -183000000 | M21: =E15 | N21: =F15 | O21: =G15
A22: Net Income after Non-Controlling/Minority Interests | B22: 94680000000 | C22: 99803000000 | D22: 96995000000 | E22: 93736000000 | F22: 112010000000 | G22: 117777000000 | I22: =A16 -> Interest Expense Net of Capitalized Interest | J22: =B16 -> -2645000000 | K22: =C16 -> -2931000000 | L22: =D16 -> -3933000000 | M22: =E16 | N22: =F16 | O22: =G16
A23: Net Income Available to Common Stockholders | B23: 94680000000 | C23: 99803000000 | D23: 96995000000 | E23: 93736000000 | F23: 112010000000 | G23: 117777000000 | I23: =A17 -> Interest Income | J23: =B17 -> 2843000000 | K23: =C17 -> 2825000000 | L23: =D17 -> 3750000000 | M23: =E17 | N23: =F17 | O23: =G17
A24: Diluted Net Income Available to Common Stockholders | B24: 94680000000 | C24: 99803000000 | D24: 96995000000 | E24: 93736000000 | F24: 112010000000 | G24: 117777000000 | I24: =A18 -> Pretax Income | J24: =B18 -> 109207000000 | K24: =C18 -> 119103000000 | L24: =D18 -> 113736000000 | M24: =E18 -> 123485000000 | N24: =F18 -> 132729000000 | O24: =G18 -> 141147000000
A25: Income Statement Supplemental Section | I25: =A19 -> Provision for Income Tax | J25: =B19 -> -14527000000 | K25: =C19 -> -19300000000 | L25: =D19 -> -16741000000 | M25: =E19 -> -29749000000 | N25: =F19 -> -20719000000 | O25: =G19 -> -23370000000
A26: Reported Normalized and Operating Income/Expense Supplemental Section | I26: =A20 -> Net Income before Extraordinary Items and Discontinued Operations | J26: =B20 -> 94680000000 | K26: =C20 -> 99803000000 | L26: =D20 -> 96995000000 | M26: =E20 -> 93736000000 | N26: =F20 -> 112010000000 | O26: =G20 -> 117777000000
A27: Total Revenue as Reported, Supplemental | B27: 365817000000 | C27: 394328000000 | D27: 383285000000 | E27: 391035000000 | F27: 416161000000 | G27: 435617000000 | I27: =A21 -> Net Income after Extraordinary Items and Discontinued Operations | J27: =B21 -> 94680000000 | K27: =C21 -> 99803000000 | L27: =D21 -> 96995000000 | M27: =E21 -> 93736000000 | N27: =F21 -> 112010000000 | O27: =G21 -> 117777000000
A28: Reported Operating Expense | B28: -43887000000 | C28: -51345000000 | D28: -54847000000 | E28: -57467000000 | F28: -62151000000 | G28: -65087000000 | I28: =A22 -> Net Income after Non-Controlling/Minority Interests | J28: =B22 -> 94680000000 | K28: =C22 -> 99803000000 | L28: =D22 -> 96995000000 | M28: =E22 -> 93736000000 | N28: =F22 -> 112010000000 | O28: =G22 -> 117777000000
A29: Reported Total Operating Profit/Loss | B29: 108949000000 | C29: 119437000000 | D29: 114301000000 | E29: 123216000000 | F29: 133050000000 | G29: 141070000000 | I29: =A23 -> Net Income Available to Common Stockholders | J29: =B23 -> 94680000000 | K29: =C23 -> 99803000000 | L29: =D23 -> 96995000000 | M29: =E23 -> 93736000000 | N29: =F23 -> 112010000000 | O29: =G23 -> 117777000000
A30: Reported Effective Tax Rate | B30: 0.133 | C30: 0.162 | D30: 0.147 | E30: 0.241 | F30: 0.156 | I30: =A24 -> Diluted Net Income Available to Common Stockholders | J30: =B24 -> 94680000000 | K30: =C24 -> 99803000000 | L30: =D24 -> 96995000000 | M30: =E24 -> 93736000000 | N30: =F24 -> 112010000000 | O30: =G24 -> 117777000000
A31: Reported Normalized Income | E31: 103982000000 | I31: =A25 -> Income Statement Supplemental Section | J31: =B25 | K31: =C25 | L31: =D25 | M31: =E25 | N31: =F25 | O31: =G25
A32: Basic EPS | B32: 5.67 | C32: 6.15 | D32: 6.16 | E32: 6.11 | F32: 7.49 | G32: 7.92 | I32: =A26 -> Reported Normalized and Operating Income/Expense Supplemental Section | J32: =B26 | K32: =C26 | L32: =D26 | M32: =E26 | N32: =F26 | O32: =G26
A33: Basic EPS from Continuing Operations | B33: 5.67 | C33: 6.15 | D33: 6.16 | E33: 6.11 | F33: 7.49 | G33: 7.92 | I33: =A27 -> Total Revenue as Reported, Supplemental | J33: =B27 -> 365817000000 | K33: =C27 -> 394328000000 | L33: =D27 -> 383285000000 | M33: =E27 -> 391035000000 | N33: =F27 -> 416161000000 | O33: =G27 -> 435617000000
A34: Diluted EPS | B34: 5.61 | C34: 6.11 | D34: 6.13 | E34: 6.08 | F34: 7.46 | G34: 7.91 | I34: =A28 -> Reported Operating Expense | J34: =B28 -> -43887000000 | K34: =C28 -> -51345000000 | L34: =D28 -> -54847000000 | M34: =E28 -> -57467000000 | N34: =F28 -> -62151000000 | O34: =G28 -> -65087000000
A35: Diluted EPS from Continuing Operations | B35: 5.61 | C35: 6.11 | D35: 6.13 | E35: 6.08 | F35: 7.46 | G35: 7.9 | I35: =A29 -> Reported Total Operating Profit/Loss | J35: =B29 -> 108949000000 | K35: =C29 -> 119437000000 | L35: =D29 -> 114301000000 | M35: =E29 -> 123216000000 | N35: =F29 -> 133050000000 | O35: =G29 -> 141070000000
A36: Basic Weighted Average Shares Outstanding | B36: 16701272000 | C36: 16215963000 | D36: 15744231000 | E36: 15343783000 | F36: 14948500000 | G36: 14865108500 | I36: =A30 -> Reported Effective Tax Rate | J36: =B30 -> 0.133 | K36: =C30 -> 0.162 | L36: =D30 -> 0.147 | M36: =E30 -> 0.241 | N36: =F30 -> 0.156 | O36: =G30
A37: Diluted Weighted Average Shares Outstanding | B37: 16864919000 | C37: 16325819000 | D37: 15812547000 | E37: 15408095000 | F37: 15004697000 | G37: 14919569750 | I37: =A31 -> Reported Normalized Income | J37: =B31 | K37: =C31 | L37: =D31 | M37: =E31 -> 103982000000 | N37: =F31 | O37: =G31
A38: Total Dividend Per Share | B38: 0.85 | C38: 0.9 | D38: 0.94 | E38: 0.98 | F38: 1.02 | G38: 1.03 | I38: =A32 -> Basic EPS | J38: =B32 -> 5.67 | K38: =C32 -> 6.15 | L38: =D32 -> 6.16 | M38: =E32 -> 6.11 | N38: =F32 -> 7.49 | O38: =G32 -> 7.92
A39: Regular Dividend Per Share Calc | B39: 0.85 | C39: 0.9 | D39: 0.94 | E39: 0.98 | F39: 1.02 | G39: 1.03 | I39: =A33 -> Basic EPS from Continuing Operations | J39: =B33 -> 5.67 | K39: =C33 -> 6.15 | L39: =D33 -> 6.16 | M39: =E33 -> 6.11 | N39: =F33 -> 7.49 | O39: =G33 -> 7.92
A40: Reported Normalized Diluted EPS | E40: 6.75 | I40: =A34 -> Diluted EPS | J40: =B34 -> 5.61 | K40: =C34 -> 6.11 | L40: =D34 -> 6.13 | M40: =E34 -> 6.08 | N40: =F34 -> 7.46 | O40: =G34 -> 7.91
...

Sheet Income Statement
B1: Income Statement | I1: CHECK | J1: =AND('Raw (Income Statement)'!P7,'Raw (Income Statement)'!P13) -> TRUE
B2: Historical Financial Analysis | All figures in USD ($millions) | Inputs in Blue
B4: USD ($millions) | C4: ="FY"&'Raw (Income Statement)'!B2 -> FY2021 | D4: ="FY"&'Raw (Income Statement)'!C2 -> FY2022 | E4: ="FY"&'Raw (Income Statement)'!D2 -> FY2023 | F4: ="FY"&'Raw (Income Statement)'!E2 -> FY2024 | G4: ="FY"&'Raw (Income Statement)'!F2 -> FY2025 | H4: ="FY"&(MID(G4,3,4)+1) -> FY2026 | I4: ="FY"&(MID(H4,3,4)+1) -> FY2027 | J4: ="FY"&(MID(I4,3,4)+1) -> FY2028 | K4: ="FY"&(MID(J4,3,4)+1) -> FY2029 | L4: ="FY"&(MID(K4,3,4)+1) -> FY2030
B6: REVENUE | H6: ="PROJECTED " & B6 -> PROJECTED REVENUE
B7: Product Revenue | C7: ='Raw (Income Statement)'!J5 -> 297392000000 | D7: ='Raw (Income Statement)'!K5 -> 316199000000 | E7: ='Raw (Income Statement)'!L5 -> 298085000000 | F7: ='Raw (Income Statement)'!M5 -> 294866000000 | G7: ='Raw (Income Statement)'!N5 -> 307003000000 | H7: =G7*(1+'Assumptions & Drivers'!E7) -> 3.1963957e+11 | I7: =H7*(1+'Assumptions & Drivers'!F7) -> 3.3279628e+11 | J7: =I7*(1+'Assumptions & Drivers'!G7) -> 3.4649453e+11 | K7: =J7*(1+'Assumptions & Drivers'!H7) -> 3.6075661e+11 | L7: =K7*(1+'Assumptions & Drivers'!I7) -> 3.7560574e+11
B8: Service Revenue | C8: ='Raw (Income Statement)'!J6 -> 68425000000 | D8: ='Raw (Income Statement)'!K6 -> 78129000000 | E8: ='Raw (Income Statement)'!L6 -> 85200000000 | F8: ='Raw (Income Statement)'!M6 -> 96169000000 | G8: ='Raw (Income Statement)'!N6 -> 109158000000 | H8: =G8*(1+'Assumptions & Drivers'!E8) -> 1.2390135e+11 | I8: =H8*(1+'Assumptions & Drivers'!F8) -> 1.40636e+11 | J8: =I8*(1+'Assumptions & Drivers'!G8) -> 1.5963091e+11 | K8: =J8*(1+'Assumptions & Drivers'!H8) -> 1.8119135e+11 | L8: =K8*(1+'Assumptions & Drivers'!I8) -> 2.0566383e+11
B9: Other Revenue | C9: 0 | D9: 0 | E9: 0 | F9: 0 | G9: 0 | H9: 0 | I9: 0 | J9: 0 | K9: 0 | L9: 0
B10: Total Revenue (Net Sales) | C10: =SUM(C7:C9) -> 365817000000 | D10: =SUM(D7:D9) -> 394328000000 | E10: =SUM(E7:E9) -> 383285000000 | F10: =SUM(F7:F9) -> 391035000000 | G10: =SUM(G7:G9) -> 416161000000 | H10: =SUM(H7:H9) -> 4.4354092e+11 | I10: =SUM(I7:I9) -> 4.7343228e+11 | J10: =SUM(J7:J9) -> 5.0612544e+11 | ... L10: =SUM(L7:L9) -> 5.8126957e+11
B11: Revenue Growth YoY | D11: =D10/C10-1 -> 0.077937876 | E11: =E10/D10-1 -> -0.028004605 | F11: =F10/E10-1 -> 0.020219941 | G11: =G10/F10-1 -> 0.064255118 | H11: =H10/G10-1 -> 0.065791658 | I11: =I10/H10-1 -> 0.067392559 | J11: =J10/I10-1 -> 0.069055612 | K11: =K10/J10-1 -> 0.070777957 | L11: =L10/K10-1 -> 0.072556068
B13: COST OF GOODS SOLD (COGS) | H13: ="PROJECTED " & B13 -> PROJECTED COST OF GOODS SOLD (COGS)
B14: Cost of Products Sold | C14: ='Raw (Income Statement)'!J11 -> 192266000000 | D14: ='Raw (Income Statement)'!K11 -> 201471000000 | E14: ='Raw (Income Statement)'!L11 -> 189282000000 | F14: ='Raw (Income Statement)'!M11 -> 185233000000 | G14: ='Raw (Income Statement)'!N11 -> 194116000000 | H14: =H7*(1-'Assumptions & Drivers'!E11) -> 2.0233185e+11 | I14: =I7*(1-'Assumptions & Drivers'!F11) -> 2.0899606e+11 | J14: =J7*(1-'Assumptions & Drivers'!G11) -> 2.1586609e+11 | K14: =K7*(1-'Assumptions & Drivers'!H11) -> 2.2727667e+11 | L14: =L7*(1-'Assumptions & Drivers'!I11) -> 2.3663162e+11
B15: Cost of Services Sold | C15: ='Raw (Income Statement)'!J12 -> 20715000000 | D15: ='Raw (Income Statement)'!K12 -> 22075000000 | E15: ='Raw (Income Statement)'!L12 -> 24855000000 | F15: ='Raw (Income Statement)'!M12 -> 25119000000 | G15: ='Raw (Income Statement)'!N12 -> 26844000000 | H15: =H8*(1-'Assumptions & Drivers'!E12) -> 3.0108028e+10 | I15: =I8*(1-'Assumptions & Drivers'!F12) -> 3.3471368e+10 | J15: =J8*(1-'Assumptions & Drivers'!G12) -> 3.7194001e+10 | K15: =K8*(1-'Assumptions & Drivers'!H12) -> 4.5297836e+10 | L15: =L8*(1-'Assumptions & Drivers'!I12) -> 5.1415957e+10
B16: Depreciation in COGS | C16: 0 | D16: 0 | E16: 0 | F16: 0 | G16: 0 | H16: 0 | I16: 0 | J16: 0 | K16: 0 | L16: 0
B17: Other COGS | C17: 0 | D17: 0 | E17: 0 | F17: 0 | G17: 0 | H17: 0 | I17: 0 | J17: 0 | K17: 0 | L17: 0
B18: Total COGS | C18: =SUM(C14:C17) -> 212981000000 | D18: =SUM(D14:D17) -> 223546000000 | E18: =SUM(E14:E17) -> 214137000000 | F18: =SUM(F14:F17) -> 210352000000 | G18: =SUM(G14:G17) -> 220960000000 | H18: =SUM(H14:H17) -> 2.3243988e+11 | I18: =SUM(I14:I17) -> 2.4246743e+11 | J18: =SUM(J14:J17) -> 2.5306009e+11 | ... L18: =SUM(L14:L17) -> 2.8804758e+11
B19: COGS YoY | D19: =D18/C18-1 -> 0.049605364 | E19: =E18/D18-1 -> -0.042089771 | F19: =F18/E18-1 -> -0.0176756 | G19: =G18/F18-1 -> 0.050429756 | H19: =H18/G18-1 -> 0.051954549 | I19: =I18/H18-1 -> 0.043140421 | J19: =J18/I18-1 -> 0.043686947 | K19: =K18/J18-1 -> 0.077113742 | L19: =L18/K18-1 -> 0.056766395
B21: GROSS PROFIT | C21: =C10-C18 -> 152836000000 | D21: =D10-D18 -> 170782000000 | E21: =E10-E18 -> 169148000000 | F21: =F10-F18 -> 180683000000 | G21: =G10-G18 -> 195201000000 | H21: =H10-H18 -> 2.1110105e+11 | I21: =I10-I18 -> 2.3096485e+11 | J21: =J10-J18 -> 2.5306534e+11 | ... L21: =L10-L18 -> 2.93222e+11
B22: Gross Margin % | C22: =C21/C10 -> 0.4177936 | D22: =D21/D10 -> 0.43309631 | E22: =E21/E10 -> 0.4413113 | F22: =F21/F10 -> 0.4620635 | G22: =G21/G10 -> 0.46905164 | H22: =H21/H10 -> 0.47594491 | I22: =I21/I10 -> 0.48785192 | J22: =J21/J10 -> 0.50000519 | ... L22: =L21/L10 -> 0.50445097
B24: OPERATING EXPENSES | H24: ="PROJECTED " & B24 -> PROJECTED OPERATING EXPENSES
B25: Research & Development | C25: =ABS('Raw (Income Statement)'!J16) -> 21914000000 | D25: =ABS('Raw (Income Statement)'!K16) -> 26251000000 | E25: =ABS('Raw (Income Statement)'!L16) -> 29915000000 | F25: =ABS('Raw (Income Statement)'!M16) -> 31370000000 | G25: =ABS('Raw (Income Statement)'!N16) -> 34550000000 | H25: =H10*'Assumptions & Drivers'!E13 -> 3.7257437e+10 | I25: =I10*'Assumptions & Drivers'!F13 -> 3.9294879e+10 | J25: =J10*'Assumptions & Drivers'!G13 -> 4.1502286e+10 | K25: =K10*'Assumptions & Drivers'!H13 -> 4.3897785e+10 | L25: =L10*'Assumptions & Drivers'!I13 -> 4.6501566e+10
B26: Sales & Marketing
B27: General & Administrative
B28: SG&A | C28: =ABS('Raw (Income Statement)'!J15) -> 21973000000 | D28: =ABS('Raw (Income Statement)'!K15) -> 25094000000 | E28: =ABS('Raw (Income Statement)'!L15) -> 24932000000 | F28: =ABS('Raw (Income Statement)'!M15) -> 26097000000 | G28: =ABS('Raw (Income Statement)'!N15) -> 27601000000 | H28: =H10*'Assumptions & Drivers'!E14 -> 2.883016e+10 | I28: =I10*'Assumptions & Drivers'!F14 -> 3.0299666e+10 | J28: =J10*'Assumptions & Drivers'!G14 -> 3.1885902e+10 | K28: =K10*'Assumptions & Drivers'!H14 -> 3.3600774e+10 | L28: =L10*'Assumptions & Drivers'!I14 -> 3.5457444e+10
B29: Depreciation & Amortization (ex. COGS) | C29: 0 | D29: 0 | E29: 0 | F29: 0 | G29: 0 | H29: 0 | I29: 0 | J29: 0 | K29: 0 | L29: 0
B30: Restructuring & Other Charges | C30: 0 | D30: 0 | E30: 0 | F30: 0 | G30: 0 | H30: 0 | I30: 0 | J30: 0 | K30: 0 | L30: 0
B31: Other Operating Expenses / (Income) | C31: 0 | D31: 0 | E31: 0 | F31: 0 | G31: 0 | H31: 0 | I31: 0 | J31: 0 | K31: 0 | L31: 0
B32: Total Operating Expenses | C32: =SUM(C25:C31) -> 43887000000 | D32: =SUM(D25:D31) -> 51345000000 | E32: =SUM(E25:E31) -> 54847000000 | F32: =SUM(F25:F31) -> 57467000000 | G32: =SUM(G25:G31) -> 62151000000 | H32: =SUM(H25:H31) -> 6.6087597e+10 | I32: =SUM(I25:I31) -> 6.9594545e+10 | J32: =SUM(J25:J31) -> 7.3388188e+10 | ... L32: =SUM(L25:L31) -> 8.195901e+10
B34: OPERATING INCOME (EBIT) | C34: =C21-C32 -> 108949000000 | D34: =D21-D32 -> 119437000000 | E34: =E21-E32 -> 114301000000 | F34: =F21-F32 -> 123216000000 | G34: =G21-G32 -> 133050000000 | H34: =H21-H32 -> 1.4501345e+11 | I34: =I21-I32 -> 1.613703e+11 | J34: =J21-J32 -> 1.7967715e+11 | ... L34: =L21-L32 -> 2.1126299e+11
B35: Operating Margin (EBIT) % | C35: =C34/C10 -> 0.29782378 | D35: =D34/D10 -> 0.30288744 | E35: =E34/E10 -> 0.29821412 | F35: =F34/F10 -> 0.31510223 | G35: =G34/G10 -> 0.319708 | H35: =H34/H10 -> 0.32694491 | I35: =I34/I10 -> 0.34085192 | J35: =J34/J10 -> 0.35500519 | ... L35: =L34/L10 -> 0.36345097
B37: NON-OPERATING ITEMS | H37: ="PROJECTED " & B37 -> PROJECTED NON-OPERATING ITEMS
B38: Interest Expense | C38: ='Raw (Income Statement)'!J22 -> -2645000000 | D38: ='Raw (Income Statement)'!K22 -> -2931000000 | E38: ='Raw (Income Statement)'!L22 -> -3933000000 | F38: ='Raw (Income Statement)'!M22 | G38: ='Raw (Income Statement)'!N22 | H38: =-78328*'Assumptions & Drivers'!E292 -> 0 | I38: =-78328*'Assumptions & Drivers'!F292 -> 0 | J38: =-78328*'Assumptions & Drivers'!G292 -> 0 | K38: =-78328*'Assumptions & Drivers'!H292 -> 0 | L38: =-78328*'Assumptions & Drivers'!I292 -> 0
B39: Interest Income | C39: ='Raw (Income Statement)'!J23 -> 2843000000 | D39: ='Raw (Income Statement)'!K23 -> 2825000000 | E39: ='Raw (Income Statement)'!L23 -> 3750000000 | F39: ='Raw (Income Statement)'!M23 | G39: ='Raw (Income Statement)'!N23 | H39: =-78328*'Assumptions & Drivers'!E293 -> 0 | I39: =-78328*'Assumptions & Drivers'!F293 -> 0 | J39: =-78328*'Assumptions & Drivers'!G293 -> 0 | K39: =-78328*'Assumptions & Drivers'!H293 -> 0 | L39: =-78328*'Assumptions & Drivers'!I293 -> 0
B40: Gain / (Loss) on Investments | C40: 0 | D40: 0 | E40: 0 | F40: 0 | G40: 0 | H40: 0 | I40: 0 | J40: 0 | K40: 0 | L40: 0
B41: Other Non-Operating Income / (Expense) | C41: ='Raw (Income Statement)'!J19 -> 60000000 | D41: ='Raw (Income Statement)'!K19 -> -228000000 | E41: ='Raw (Income Statement)'!L19 -> -382000000 | F41: ='Raw (Income Statement)'!M19 -> 269000000 | G41: ='Raw (Income Statement)'!N19 -> -321000000 | H41: 0 | I41: 0 | J41: 0 | K41: 0 | L41: 0
B42: Total Non-Operating Items | C42: =SUM(C38:C41) -> 258000000 | D42: =SUM(D38:D41) -> -334000000 | E42: =SUM(E38:E41) -> -565000000 | F42: =SUM(F38:F41) -> 269000000 | G42: =SUM(G38:G41) -> -321000000 | H42: =SUM(H38:H41) -> 0 | I42: =SUM(I38:I41) -> 0 | J42: =SUM(J38:J41) -> 0 | ... L42: =SUM(L38:L41) -> 0
B44: INCOME BEFORE TAXES (EBT) | C44: =C34+C42 -> 109207000000 | D44: =D34+D42 -> 119103000000 | E44: =E34+E42 -> 113736000000 | F44: =F34+F42 -> 123485000000 | G44: =G34+G42 -> 132729000000 | H44: =H34+H42 -> 1.4501345e+11 | I44: =I34+I42 -> 1.613703e+11 | J44: =J34+J42 -> 1.7967715e+11 | ... L44: =L34+L42 -> 2.1126299e+11
B46: INCOME TAXES | H46: ="PROJECTED " & B46 -> PROJECTED INCOME TAXES
B47: Income Tax Expense / (Benefit) | C47: =ABS('Raw (Income Statement)'!J25) -> 14527000000 | D47: =ABS('Raw (Income Statement)'!K25) -> 19300000000 | E47: =ABS('Raw (Income Statement)'!L25) -> 16741000000 | F47: =ABS('Raw (Income Statement)'!M25) -> 29749000000 | G47: =ABS('Raw (Income Statement)'!N25) -> 20719000000 | H47: =H44*'Assumptions & Drivers'!E27 -> 3.0452824e+10 | I47: =I44*'Assumptions & Drivers'!F27 -> 3.3887764e+10 | J47: =J44*'Assumptions & Drivers'!G27 -> 3.7732202e+10 | K47: =K44*'Assumptions & Drivers'!H27 -> 4.0293729e+10 | L47: =L44*'Assumptions & Drivers'!I27 -> 4.4365227e+10
B49: NET INCOME | C49: =C44-C47 -> 94680000000 | D49: =D44-D47 -> 99803000000 | E49: =E44-E47 -> 96995000000 | F49: =F44-F47 -> 93736000000 | G49: =G44-G47 -> 112010000000 | H49: =H44-H47 -> 1.1456062e+11 | I49: =I44-I47 -> 1.2748254e+11 | J49: =J44-J47 -> 1.4194495e+11 | ... L49: =L44-L47 -> 1.6689776e+11
B50: Net Profit Margin % | C50: =C49/C10 -> 0.25881793 | D50: =D49/D10 -> 0.25309641 | E50: =E49/E10 -> 0.25306234 | F50: =F49/F10 -> 0.23971256 | G50: =G49/G10 -> 0.26915064 | H50: =H49/H10 -> 0.25828648 | I50: =I49/I10 -> 0.26927302 | J50: =J49/J10 -> 0.2804541 | ... L50: =L49/L10 -> 0.28712626
...

Sheet Cash Flow Statement
B1: Cash Flow Statement | I1: CHECK | J1: =AND('Raw (CF Statement)'!P33,'Raw (CF Statement)'!P55) -> TRUE
B2: Historical Financial Analysis | All figures in USD ($millions) | Inputs in Blue
B4: USD ($millions) | C4: FY2021 | D4: FY2022 | E4: FY2023 | F4: FY2024 | G4: FY2025 | H4: ="FY"&(MID(G4,3,4)+1) -> FY2026 | I4: ="FY"&(MID(H4,3,4)+1) -> FY2027 | J4: ="FY"&(MID(I4,3,4)+1) -> FY2028 | K4: ="FY"&(MID(J4,3,4)+1) -> FY2029 | L4: ="FY"&(MID(K4,3,4)+1) -> FY2030
B6: OPERATING ACTIVITIES | H6: ="PROJECTED " & B6 -> PROJECTED OPERATING ACTIVITIES
B7: Net Income | C7: ='Raw (CF Statement)'!J6 -> 94680000000 | D7: ='Raw (CF Statement)'!K6 -> 99803000000 | E7: ='Raw (CF Statement)'!L6 -> 96995000000 | F7: ='Raw (CF Statement)'!M6 -> 93736000000 | G7: ='Raw (CF Statement)'!N6 -> 112010000000 | H7: ='Income Statement'!H49 -> 1.1456062e+11 | I7: ='Income Statement'!I49 -> 1.2748254e+11 | J7: ='Income Statement'!J49 -> 1.4194495e+11 | K7: ='Income Statement'!K49 -> 1.5158117e+11 | L7: ='Income Statement'!L49 -> 1.6689776e+11
B8: Non-Cash Adjustments:
B9: Depreciation & Amortization | C9: ='Raw (CF Statement)'!J9 -> 11284000000 | D9: ='Raw (CF Statement)'!K9 -> 11104000000 | E9: ='Raw (CF Statement)'!L9 -> 11519000000 | F9: ='Raw (CF Statement)'!M9 -> 11445000000 | G9: ='Raw (CF Statement)'!N9 -> 11698000000 | H9: ='Income Statement'!H55 -> 1.2419146e+10 | I9: ='Income Statement'!I55 -> 1.3256104e+10 | J9: ='Income Statement'!J55 -> 1.3665387e+10 | K9: ='Income Statement'!K55 -> 1.4632595e+10 | L9: ='Income Statement'!L55 -> 1.5694278e+10
B10: Stock-Based Compensation | C10: ='Raw (CF Statement)'!J10 -> 7906000000 | D10: ='Raw (CF Statement)'!K10 -> 9038000000 | E10: ='Raw (CF Statement)'!L10 -> 10833000000 | F10: ='Raw (CF Statement)'!M10 -> 11688000000 | G10: ='Raw (CF Statement)'!N10 -> 12863000000 | H10: ='Income Statement'!H10*'Assumptions & Drivers'!E19 -> 1.3749769e+10 | I10: ='Income Statement'!I10*'Assumptions & Drivers'!F19 -> 1.4676401e+10 | J10: ='Income Statement'!J10*'Assumptions & Drivers'!G19 -> 1.5183763e+10 | K10: ='Income Statement'!K10*'Assumptions & Drivers'!H19 -> 1.6258439e+10 | L10: ='Income Statement'!L10*'Assumptions & Drivers'!I19 -> 1.6856818e+10
B11: Deferred Income Taxes | C11: ='Raw (CF Statement)'!J12 -> -4774000000 | D11: ='Raw (CF Statement)'!K12 -> 895000000 | E11: ='Raw (CF Statement)'!L12 | F11: ='Raw (CF Statement)'!M12 | G11: ='Raw (CF Statement)'!N12 | H11: 0 | I11: 0 | J11: 0 | K11: 0 | L11: 0
B12: Impairment Charges | C12: 0 | D12: 0 | E12: 0 | F12: 0 | G12: 0 | H12: 0 | I12: 0 | J12: 0 | K12: 0 | L12: 0
B13: Other Non-Cash Items | C13: ='Raw (CF Statement)'!J11 -> -147000000 | D13: ='Raw (CF Statement)'!K11 -> 111000000 | E13: ='Raw (CF Statement)'!L11 -> -2227000000 | F13: ='Raw (CF Statement)'!M11 -> -2266000000 | G13: ='Raw (CF Statement)'!N11 -> -89000000 | H13: 0 | I13: 0 | J13: 0 | K13: 0 | L13: 0
B14: Changes in Working Capital:
B15: (Increase) / Decrease in Accounts Receivable & Non-Trade Receivables | C15: ='Raw (CF Statement)'!J15 -> -14028000000 | D15: ='Raw (CF Statement)'!K15 -> -9343000000 | E15: ='Raw (CF Statement)'!L15 -> -417000000 | F15: ='Raw (CF Statement)'!M15 -> -5144000000 | G15: ='Raw (CF Statement)'!N15 -> -7029000000 | H15: =-('Balance Sheet'!H10+'Balance Sheet'!H11-'Balance Sheet'!G10-'Balance Sheet'!G11) -> -4340846726 | I15: =-('Balance Sheet'!I10+'Balance Sheet'!I11-'Balance Sheet'!H10-'Balance Sheet'!H11) -> -4362806639 | J15: =-('Balance Sheet'!J10+'Balance Sheet'!J11-'Balance Sheet'!I10-'Balance Sheet'!I11) -> -4715462965 | K15: =-('Balance Sheet'!K10+'Balance Sheet'!K11-'Balance Sheet'!J10-'Balance Sheet'!J11) -> -6354286417 | L15: =-('Balance Sheet'!L10+'Balance Sheet'!L11-'Balance Sheet'!K10-'Balance Sheet'!K11) -> -6081872842
B16: (Increase) / Decrease in Inventories | C16: ='Raw (CF Statement)'!J14 -> -2642000000 | D16: ='Raw (CF Statement)'!K14 -> 1484000000 | E16: ='Raw (CF Statement)'!L14 -> -1618000000 | F16: ='Raw (CF Statement)'!M14 -> -1046000000 | G16: ='Raw (CF Statement)'!N14 -> 1400000000 | H16: =-('Balance Sheet'!H12-'Balance Sheet'!G12) -> -297076111 | I16: =-('Balance Sheet'!I12-'Balance Sheet'!H12) -> -259492915 | J16: =-('Balance Sheet'!J12-'Balance Sheet'!I12) -> -274116763 | K16: =-('Balance Sheet'!K12-'Balance Sheet'!J12) -> -504993665 | L16: =-('Balance Sheet'!L12-'Balance Sheet'!K12) -> -400411954
B17: (Increase) / Decrease in Prepaid & Other | C17: ='Raw (CF Statement)'!J18 -> -8042000000 | D17: ='Raw (CF Statement)'!K18 -> -6499000000 | E17: ='Raw (CF Statement)'!L18 -> -5684000000 | F17: ='Raw (CF Statement)'!M18 -> -11731000000 | G17: ='Raw (CF Statement)'!N18 -> -9197000000 | H17: =-('Balance Sheet'!H13-'Balance Sheet'!G13) -> -959571335 | I17: =-('Balance Sheet'!I13-'Balance Sheet'!H13) -> -1047588435 | J17: =-('Balance Sheet'!J13-'Balance Sheet'!I13) -> -1145781748 | K17: =-('Balance Sheet'!K13-'Balance Sheet'!J13) -> -1255455262 | L17: =-('Balance Sheet'!L13-'Balance Sheet'!K13) -> -1378086183
B18: Increase / (Decrease) in Accounts Payable | C18: ='Raw (CF Statement)'!J19 -> 12326000000 | D18: ='Raw (CF Statement)'!K19 -> 9448000000 | E18: ='Raw (CF Statement)'!L19 -> -1889000000 | F18: ='Raw (CF Statement)'!M19 -> 6020000000 | G18: ='Raw (CF Statement)'!N19 -> 902000000 | H18: ='Balance Sheet'!H31-'Balance Sheet'!G31 -> 3629544796 | I18: ='Balance Sheet'!I31-'Balance Sheet'!H31 -> 3170369889 | J18: ='Balance Sheet'!J31-'Balance Sheet'!I31 -> 3349037606 | K18: ='Balance Sheet'!K31-'Balance Sheet'!J31 -> 6169789693 | L18: ='Balance Sheet'!L31-'Balance Sheet'!K31 -> 4892056508
B19: Increase / (Decrease) in Accrued Liabilities | C19: ='Raw (CF Statement)'!J22 -> 5799000000 | D19: ='Raw (CF Statement)'!K22 -> 5632000000 | E19: ='Raw (CF Statement)'!L22 -> 3031000000 | F19: ='Raw (CF Statement)'!M22 -> 15552000000 | G19: ='Raw (CF Statement)'!N22 -> -11076000000 | H19: ='Balance Sheet'!H35-'Balance Sheet'!G35 -> 4367710814 | I19: ='Balance Sheet'!I35-'Balance Sheet'!H35 -> 4768340995 | J19: ='Balance Sheet'!J35-'Balance Sheet'!I35 -> 5215290568 | K19: ='Balance Sheet'!K35-'Balance Sheet'!J35 -> 5714494925 | L19: ='Balance Sheet'!L35-'Balance Sheet'!K35 -> 6272677920
B20: Increase / (Decrease) in Deferred Revenue | C20: ='Raw (CF Statement)'!J23 -> 1676000000 | D20: ='Raw (CF Statement)'!K23 -> 478000000 | E20: ='Raw (CF Statement)'!L23 | F20: ='Raw (CF Statement)'!M23 | G20: ='Raw (CF Statement)'!N23 | H20: ='Balance Sheet'!H34-'Balance Sheet'!G34 -> 1223007362 | I20: ='Balance Sheet'!I34-'Balance Sheet'!H34 -> 1388192012 | J20: ='Balance Sheet'!J34-'Balance Sheet'!I34 -> 1575687214 | K20: ='Balance Sheet'!K34-'Balance Sheet'!J34 -> 1788506326 | L20: ='Balance Sheet'!L34-'Balance Sheet'!K34 -> 2030069706
B21: Other Changes in Working Capital | C21: 0 | D21: 0 | E21: 0 | F21: 0 | G21: 0 | H21: 0 | I21: 0 | J21: 0 | K21: 0 | L21: 0
B22: Net Cash from Operating Activities (CFO) | C22: =SUM(C7:C21) -> 104038000000 | D22: =SUM(D7:D21) -> 122151000000 | E22: =SUM(E7:E21) -> 110543000000 | F22: =SUM(F7:F21) -> 118254000000 | G22: =SUM(G7:G21) -> 111482000000 | H22: =SUM(H7:H21) -> 1.4435231e+11 | I22: =SUM(I7:I21) -> 1.5907206e+11 | J22: =SUM(J7:J21) -> 1.7479876e+11 | ... L22: =SUM(L7:L21) -> 2.0478329e+11
B24: INVESTING ACTIVITIES | H24: ="PROJECTED " & B24 -> PROJECTED INVESTING ACTIVITIES
B25: Capital Expenditures (CapEx) | C25: ='Raw (CF Statement)'!J27 -> -11085000000 | D25: ='Raw (CF Statement)'!K27 -> -10708000000 | E25: ='Raw (CF Statement)'!L27 -> -10959000000 | F25: ='Raw (CF Statement)'!M27 -> -9447000000 | G25: ='Raw (CF Statement)'!N27 -> -12715000000 | H25: =-'Income Statement'!H10*'Assumptions & Drivers'!E18 -> -1.3749769e+10 | I25: =-'Income Statement'!I10*'Assumptions & Drivers'!F18 -> -1.4202968e+10 | J25: =-'Income Statement'!J10*'Assumptions & Drivers'!G18 -> -1.4677638e+10 | K25: =-'Income Statement'!K10*'Assumptions & Drivers'!H18 -> -1.5716491e+10 | L25: =-'Income Statement'!L10*'Assumptions & Drivers'!I18 -> -1.6275548e+10
B26: Purchases of Short-Term Investments | C26: ='Raw (CF Statement)'!J29 -> -109689000000 | D26: ='Raw (CF Statement)'!K29 -> -76923000000 | E26: ='Raw (CF Statement)'!L29 -> -29513000000 | F26: ='Raw (CF Statement)'!M29 -> -48656000000 | G26: ='Raw (CF Statement)'!N29 -> -24407000000 | H26: 0 | I26: 0 | J26: 0 | K26: 0 | L26: 0
B27: Maturities of Short-Term Investments | C27: ='Raw (CF Statement)'!J31 -> 59023000000 | D27: ='Raw (CF Statement)'!K31 -> 29917000000 | E27: ='Raw (CF Statement)'!L31 -> 39686000000 | F27: ='Raw (CF Statement)'!M31 -> 51211000000 | G27: ='Raw (CF Statement)'!N31 -> 40907000000 | H27: ='Balance Sheet'!G9-'Balance Sheet'!H9 -> 0 | I27: ='Balance Sheet'!H9-'Balance Sheet'!I9 -> 0 | J27: ='Balance Sheet'!I9-'Balance Sheet'!J9 -> 0 | K27: ='Balance Sheet'!J9-'Balance Sheet'!K9 -> 0 | L27: ='Balance Sheet'!K9-'Balance Sheet'!L9 -> 0
B28: Proceeds from Sale of Investments | C28: ='Raw (CF Statement)'!J32 -> 47847000000 | D28: ='Raw (CF Statement)'!K32 -> 37446000000 | E28: ='Raw (CF Statement)'!L32 -> 5828000000 | F28: ='Raw (CF Statement)'!M32 -> 11135000000 | G28: ='Raw (CF Statement)'!N32 -> 12890000000 | H28: 0 | I28: 0 | J28: 0 | K28: 0 | L28: 0
B29: Acquisitions, net of Cash Acquired | C29: ='Raw (CF Statement)'!J36 -> -33000000 | D29: ='Raw (CF Statement)'!K36 -> -306000000 | E29: ='Raw (CF Statement)'!L36 | F29: ='Raw (CF Statement)'!M36 | G29: ='Raw (CF Statement)'!N36 | H29: 0 | I29: 0 | J29: 0 | K29: 0 | L29: 0
B30: Proceeds from Divestitures | C30: 0 | D30: 0 | E30: 0 | F30: 0 | G30: 0 | H30: 0 | I30: 0 | J30: 0 | K30: 0 | L30: 0
B31: Other Investing Activities | C31: ='Raw (CF Statement)'!J34 -> -608000000 | D31: ='Raw (CF Statement)'!K34 -> -1780000000 | E31: ='Raw (CF Statement)'!L34 -> -1337000000 | F31: ='Raw (CF Statement)'!M34 -> -1308000000 | G31: ='Raw (CF Statement)'!N34 -> -1480000000 | H31: ='Balance Sheet'!G24-'Balance Sheet'!H24 -> 0 | I31: ='Balance Sheet'!H24-'Balance Sheet'!I24 -> 0 | J31: ='Balance Sheet'!I24-'Balance Sheet'!J24 -> 0 | K31: ='Balance Sheet'!J24-'Balance Sheet'!K24 -> 0 | L31: ='Balance Sheet'!K24-'Balance Sheet'!L24 -> 0
B32: Net Cash from Investing Activities (CFI) | C32: =SUM(C25:C31) -> -14545000000 | D32: =SUM(D25:D31) -> -22354000000 | E32: =SUM(E25:E31) -> 3705000000 | F32: =SUM(F25:F31) -> 2935000000 | G32: =SUM(G25:G31) -> 15195000000 | H32: =SUM(H25:H31) -> -1.3749769e+10 | I32: =SUM(I25:I31) -> -1.4202968e+10 | J32: =SUM(J25:J31) -> -1.4677638e+10 | ... L32: =SUM(L25:L31) -> -1.6275548e+10
B34: FINANCING ACTIVITIES | H34: ="PROJECTED " & B34 -> PROJECTED FINANCING ACTIVITIES
B35: Taxes related to net share settlement of equity awards | C35: =-'Raw (CF Statement)'!J53 -> -6685000000 | D35: =-'Raw (CF Statement)'!K53 -> -6223000000 | E35: =-'Raw (CF Statement)'!L53 -> -5431000000 | F35: =-'Raw (CF Statement)'!M53 -> -5441000000 | G35: =-'Raw (CF Statement)'!N53 -> -5960000000 | H35: 0 | I35: 0 | J35: 0 | K35: 0 | L35: 0
B36: Proceeds from Issuance of Short-Term Debt | C36: ='Raw (CF Statement)'!J45 -> 1022000000 | D36: ='Raw (CF Statement)'!K45 -> 3955000000 | E36: ='Raw (CF Statement)'!L45 -> -3978000000 | F36: ='Raw (CF Statement)'!M45 -> 3960000000 | G36: ='Raw (CF Statement)'!N45 -> -2032000000 | H36: 0 | I36: 0 | J36: 0 | K36: 0 | L36: 0
B37: Proceeds from Issuance of Long-Term Debt | C37: ='Raw (CF Statement)'!J47 -> 20393000000 | D37: ='Raw (CF Statement)'!K47 -> 5465000000 | E37: ='Raw (CF Statement)'!L47 -> 5228000000 | F37: ='Raw (CF Statement)'!M47 -> 0 | G37: ='Raw (CF Statement)'!N47 -> 4481000000 | H37: 0 | I37: 0 | J37: 0 | K37: 0 | L37: 0
B38: Repayment of Long-Term Debt | C38: ='Raw (CF Statement)'!J48 -> -8750000000 | D38: ='Raw (CF Statement)'!K48 -> -9543000000 | E38: ='Raw (CF Statement)'!L48 -> -11151000000 | F38: ='Raw (CF Statement)'!M48 -> -9958000000 | G38: ='Raw (CF Statement)'!N48 -> -10932000000 | H38: 0 | I38: 0 | J38: 0 | K38: 0 | L38: 0
B39: Proceeds from Equity Issuance | C39: 0 | D39: 0 | E39: 0 | F39: 0 | G39: 0 | H39: 0 | I39: 0 | J39: 0 | K39: 0 | L39: 0
B40: Share Repurchases / Buybacks | C40: ='Raw (CF Statement)'!J41 -> -84866000000 | D40: ='Raw (CF Statement)'!K41 -> -89402000000 | E40: ='Raw (CF Statement)'!L41 -> -77550000000 | F40: ='Raw (CF Statement)'!M41 -> -94949000000 | G40: ='Raw (CF Statement)'!N41 -> -90711000000 | H40: =-'Assumptions & Drivers'!E32*1000000 -> -90000000000 | I40: =-'Assumptions & Drivers'!F32*1000000 -> -85000000000 | J40: =-'Assumptions & Drivers'!G32*1000000 -> -80000000000 | K40: =-'Assumptions & Drivers'!H32*1000000 -> -75000000000 | L40: =-'Assumptions & Drivers'!I32*1000000 -> -70000000000
B41: Dividends Paid | C41: ='Raw (CF Statement)'!J49 -> -14467000000 | D41: ='Raw (CF Statement)'!K49 -> -14841000000 | E41: ='Raw (CF Statement)'!L49 -> -15025000000 | F41: ='Raw (CF Statement)'!M49 -> -15234000000 | G41: ='Raw (CF Statement)'!N49 -> -15421000000 | H41: =-'Assumptions & Drivers'!E33*'Income Statement'!H53 -> -1.568625e+10 | I41: =-'Assumptions & Drivers'!F33*'Income Statement'!I53 -> -1.5957248e+10 | J41: =-'Assumptions & Drivers'!G33*'Income Statement'!J53 -> -1.6228967e+10 | K41: =-'Assumptions & Drivers'!H33*'Income Statement'!K53 -> -1.6506657e+10 | L41: =-'Assumptions & Drivers'!I33*'Income Statement'!L53 -> -1.6782791e+10
B42: Other Financing Activities | C42: =-'Raw (CF Statement)'!J54 -> 0 | D42: =-'Raw (CF Statement)'!K54 -> -160000000 | E42: =-'Raw (CF Statement)'!L54 -> -581000000 | F42: =-'Raw (CF Statement)'!M54 -> -361000000 | G42: =-'Raw (CF Statement)'!N54 -> -111000000 | H42: 0 | I42: 0 | J42: 0 | K42: 0 | L42: 0
B43: Net Cash from Financing Activities (CFF) | C43: =SUM(C35:C42) -> -93353000000 | D43: =SUM(D35:D42) -> -110749000000 | E43: =SUM(E35:E42) -> -108488000000 | F43: =SUM(F35:F42) -> -121983000000 | G43: =SUM(G35:G42) -> -120686000000 | H43: =SUM(H35:H42) -> -1.0568625e+11 | I43: =SUM(I35:I42) -> -1.0095725e+11 | J43: =SUM(J35:J42) -> -9.6228967e+10 | ... L43: =SUM(L35:L42) -> -8.6782791e+10
B45: CASH RECONCILIATION | H45: ="PROJECTED " & B45 -> PROJECTED CASH RECONCILIATION
...

Sheet Raw (CF Statement)
A1: RAW | I1: ADJUSTED
A2: AAPL_cash-flow_Annual_As_Originally_Reported | B2: 2021 | C2: 2022 | D2: 2023 | E2: 2024 | F2: 2025 | G2: TTM | I2: =A2 -> AAPL_cash-flow_Annual_As_Originally_Reported | J2: =B2 -> 2021 | K2: =C2 -> 2022 | L2: =D2 -> 2023 | M2: =E2 -> 2024 | N2: =F2 -> 2025 | O2: =G2 -> TTM
A3: Cash Flow from Operating Activities, Indirect | B3: 104038000000 | C3: 122151000000 | D3: 110543000000 | E3: 118254000000 | F3: 111482000000 | G3: 135472000000 | I3: =A3 -> Cash Flow from Operating Activities, Indirect | J3: =B3 -> 104038000000 | K3: =C3 -> 122151000000 | L3: =D3 -> 110543000000 | M3: =E3 -> 118254000000 | N3: =F3 -> 111482000000 | O3: =G3 -> 135472000000
A4: Net Cash Flow from Continuing Operating Activities, Indirect | B4: 104038000000 | C4: 122151000000 | D4: 110543000000 | E4: 118254000000 | F4: 111482000000 | G4: 135472000000 | I4: =A4 -> Net Cash Flow from Continuing Operating Activities, Indirect | J4: =B4 -> 104038000000 | K4: =C4 -> 122151000000 | L4: =D4 -> 110543000000 | M4: =E4 -> 118254000000 | N4: =F4 -> 111482000000 | O4: =G4 -> 135472000000
A5: Cash Generated from Operating Activities | B5: 104038000000 | C5: 122151000000 | D5: 110543000000 | E5: 118254000000 | F5: 111482000000 | G5: 135472000000 | I5: =A5 -> Cash Generated from Operating Activities | J5: =B5 -> 104038000000 | K5: =C5 -> 122151000000 | L5: =D5 -> 110543000000 | M5: =E5 -> 118254000000 | N5: =F5 -> 111482000000 | O5: =G5 -> 135472000000
A6: Income/Loss before Non-Cash Adjustment | B6: 94680000000 | C6: 99803000000 | D6: 96995000000 | E6: 93736000000 | F6: 112010000000 | G6: 117777000000 | I6: =A6 -> Income/Loss before Non-Cash Adjustment | J6: =B6 -> 94680000000 | K6: =C6 -> 99803000000 | L6: =D6 -> 96995000000 | M6: =E6 -> 93736000000 | N6: =F6 -> 112010000000 | O6: =G6 -> 117777000000
A7: Total Adjustments for Non-Cash Items | B7: 14269000000 | C7: 21148000000 | D7: 20125000000 | E7: 20867000000 | F7: 24472000000 | G7: 26395000000 | I7: =A7 -> Total Adjustments for Non-Cash Items | J7: =B7 -> 14269000000 | K7: =C7 -> 21148000000 | L7: =D7 -> 20125000000 | M7: =E7 -> 20867000000 | N7: =F7 -> 24472000000 | O7: =G7 -> 26395000000
A8: Depreciation, Amortization and Depletion, Non-Cash Adjustment | B8: 11284000000 | C8: 11104000000 | D8: 11519000000 | E8: 11445000000 | F8: 11698000000 | G8: 11832000000 | I8: =A8 -> Depreciation, Amortization and Depletion, Non-Cash Adjustment | J8: =B8 -> 11284000000 | K8: =C8 -> 11104000000 | L8: =D8 -> 11519000000 | M8: =E8 -> 11445000000 | N8: =F8 -> 11698000000 | O8: =G8 -> 11832000000
A9: Depreciation and Amortization, Non-Cash Adjustment | B9: 11284000000 | C9: 11104000000 | D9: 11519000000 | E9: 11445000000 | F9: 11698000000 | G9: 11832000000 | I9: =A9 -> Depreciation and Amortization, Non-Cash Adjustment | J9: =B9 -> 11284000000 | K9: =C9 -> 11104000000 | L9: =D9 -> 11519000000 | M9: =E9 -> 11445000000 | N9: =F9 -> 11698000000 | O9: =G9 -> 11832000000
A10: Stock-Based Compensation, Non-Cash Adjustment | B10: 7906000000 | C10: 9038000000 | D10: 10833000000 | E10: 11688000000 | F10: 12863000000 | G10: 13171000000 | I10: =A10 -> Stock-Based Compensation, Non-Cash Adjustment | J10: =B10 -> 7906000000 | K10: =C10 -> 9038000000 | L10: =D10 -> 10833000000 | M10: =E10 -> 11688000000 | N10: =F10 -> 12863000000 | O10: =G10 -> 13171000000
A11: Other Non-Cash Items | B11: -147000000 | C11: 111000000 | D11: -2227000000 | E11: -2266000000 | F11: -89000000 | G11: 1392000000 | I11: =A11 -> Other Non-Cash Items | J11: =B11 -> -147000000 | K11: =C11 -> 111000000 | L11: =D11 -> -2227000000 | M11: =E11 -> -2266000000 | N11: =F11 -> -89000000 | O11: =G11 -> 1392000000
A12: Deferred Taxes, Non-Cash Adjustment | B12: -4774000000 | C12: 895000000 | I12: =A12 -> Deferred Taxes, Non-Cash Adjustment | J12: =B12 -> -4774000000 | K12: =C12 -> 895000000 | L12: =D12 | M12: =E12 | N12: =F12 | O12: =G12
A13: Changes in Operating Capital | B13: -4911000000 | C13: 1200000000 | D13: -6577000000 | E13: 3651000000 | F13: -25000000000 | G13: -8700000000 | I13: =A13 -> Changes in Operating Capital | J13: =B13 -> -4911000000 | K13: =C13 -> 1200000000 | L13: =D13 -> -6577000000 | M13: =E13 -> 3651000000 | N13: =F13 -> -25000000000 | O13: =G13 -> -8700000000
A14: Change in Inventories | B14: -2642000000 | C14: 1484000000 | D14: -1618000000 | E14: -1046000000 | F14: 1400000000 | G14: 974000000 | I14: =A14 -> Change in Inventories | J14: =B14 -> -2642000000 | K14: =C14 -> 1484000000 | L14: =D14 -> -1618000000 | M14: =E14 -> -1046000000 | N14: =F14 -> 1400000000 | O14: =G14 -> 974000000
A15: Change in Trade and Other Receivables | B15: -14028000000 | C15: -9343000000 | D15: -417000000 | E15: -5144000000 | F15: -7029000000 | G15: -11164000000 | I15: =A15 -> Change in Trade and Other Receivables | J15: =B15 -> -14028000000 | K15: =C15 -> -9343000000 | L15: =D15 -> -417000000 | M15: =E15 -> -5144000000 | N15: =F15 -> -7029000000 | O15: =G15 -> -11164000000
A16: Change in Trade/Accounts Receivable | B16: -10125000000 | C16: -1823000000 | D16: -1688000000 | E16: -3788000000 | F16: -6682000000 | G16: -10432000000 | I16: =A16 -> Change in Trade/Accounts Receivable | J16: =B16 -> -10125000000 | K16: =C16 -> -1823000000 | L16: =D16 -> -1688000000 | M16: =E16 -> -3788000000 | N16: =F16 -> -6682000000 | O16: =G16 -> -10432000000
A17: Change in Other Receivables | B17: -3903000000 | C17: -7520000000 | D17: 1271000000 | E17: -1356000000 | F17: -347000000 | G17: -732000000 | I17: =A17 -> Change in Other Receivables | J17: =B17 -> -3903000000 | K17: =C17 -> -7520000000 | L17: =D17 -> 1271000000 | M17: =E17 -> -1356000000 | N17: =F17 -> -347000000 | O17: =G17 -> -732000000
A18: Change in Other Current Assets | B18: -8042000000 | C18: -6499000000 | D18: -5684000000 | E18: -11731000000 | F18: -9197000000 | G18: -20386000000 | I18: =A18 -> Change in Other Current Assets | J18: =B18 -> -8042000000 | K18: =C18 -> -6499000000 | L18: =D18 -> -5684000000 | M18: =E18 -> -11731000000 | N18: =F18 -> -9197000000 | O18: =G18 -> -20386000000
A19: Change in Payables and Accrued Expenses | B19: 12326000000 | C19: 9448000000 | D19: -1889000000 | E19: 6020000000 | F19: 902000000 | G19: 8421000000 | I19: =A19 -> Change in Payables and Accrued Expenses | J19: =B19 -> 12326000000 | K19: =C19 -> 9448000000 | L19: =D19 -> -1889000000 | M19: =E19 -> 6020000000 | N19: =F19 -> 902000000 | O19: =G19 -> 8421000000
A20: Change in Trade and Other Payables | B20: 12326000000 | C20: 9448000000 | D20: -1889000000 | E20: 6020000000 | F20: 902000000 | G20: 8421000000 | I20: =A20 -> Change in Trade and Other Payables | J20: =B20 -> 12326000000 | K20: =C20 -> 9448000000 | L20: =D20 -> -1889000000 | M20: =E20 -> 6020000000 | N20: =F20 -> 902000000 | O20: =G20 -> 8421000000
A21: Change in Trade/Accounts Payable | B21: 12326000000 | C21: 9448000000 | D21: -1889000000 | E21: 6020000000 | F21: 902000000 | G21: 8421000000 | I21: =A21 -> Change in Trade/Accounts Payable | J21: =B21 -> 12326000000 | K21: =C21 -> 9448000000 | L21: =D21 -> -1889000000 | M21: =E21 -> 6020000000 | N21: =F21 -> 902000000 | O21: =G21 -> 8421000000
A22: Change in Other Current Liabilities | B22: 5799000000 | C22: 5632000000 | D22: 3031000000 | E22: 15552000000 | F22: -11076000000 | G22: 13455000000 | I22: =A22 -> Change in Other Current Liabilities | J22: =B22 -> 5799000000 | K22: =C22 -> 5632000000 | L22: =D22 -> 3031000000 | M22: =E22 -> 15552000000 | N22: =F22 -> -11076000000 | O22: =G22 -> 13455000000
A23: Change in Deferred Assets/Liabilities | B23: 1676000000 | C23: 478000000 | I23: =A23 -> Change in Deferred Assets/Liabilities | J23: =B23 -> 1676000000 | K23: =C23 -> 478000000 | L23: =D23 | M23: =E23 | N23: =F23 | O23: =G23
A24: Cash Flow from Investing Activities | B24: -14545000000 | C24: -22354000000 | D24: 3705000000 | E24: 2935000000 | F24: 15195000000 | G24: 517000000 | I24: =A24 -> Cash Flow from Investing Activities | J24: =B24 -> -14545000000 | K24: =C24 -> -22354000000 | L24: =D24 -> 3705000000 | M24: =E24 -> 2935000000 | N24: =F24 -> 15195000000 | O24: =G24 -> 517000000
A25: Cash Flow from Continuing Investing Activities | B25: -14545000000 | C25: -22354000000 | D25: 3705000000 | E25: 2935000000 | F25: 15195000000 | G25: 517000000 | I25: =A25 -> Cash Flow from Continuing Investing Activities | J25: =B25 -> -14545000000 | K25: =C25 -> -22354000000 | L25: =D25 -> 3705000000 | M25: =E25 -> 2935000000 | N25: =F25 -> 15195000000 | O25: =G25 -> 517000000
A26: Purchase/Sale and Disposal of Property, Plant and Equipment, Net | B26: -11085000000 | C26: -10708000000 | D26: -10959000000 | E26: -9447000000 | F26: -12715000000 | G26: -12148000000 | I26: =A26 -> Purchase/Sale and Disposal of Property, Plant and Equipment, Net | J26: =B26 -> -11085000000 | K26: =C26 -> -10708000000 | L26: =D26 -> -10959000000 | M26: =E26 -> -9447000000 | N26: =F26 -> -12715000000 | O26: =G26 -> -12148000000
A27: Purchase of Property, Plant and Equipment | B27: -11085000000 | C27: -10708000000 | D27: -10959000000 | E27: -9447000000 | F27: -12715000000 | G27: -12148000000 | I27: =A27 -> Purchase of Property, Plant and Equipment | J27: =B27 -> -11085000000 | K27: =C27 -> -10708000000 | L27: =D27 -> -10959000000 | M27: =E27 -> -9447000000 | N27: =F27 -> -12715000000 | O27: =G27 -> -12148000000
A28: Purchase/Sale of Investments, Net | B28: -2819000000 | C28: -9560000000 | D28: 16001000000 | E28: 13690000000 | F28: 29390000000 | G28: 13696000000 | I28: =A28 -> Purchase/Sale of Investments, Net | J28: =B28 -> -2819000000 | K28: =C28 -> -9560000000 | L28: =D28 -> 16001000000 | M28: =E28 -> 13690000000 | N28: =F28 -> 29390000000 | O28: =G28 -> 13696000000
A29: Purchase of Investments | B29: -109689000000 | C29: -76923000000 | D29: -29513000000 | E29: -48656000000 | F29: -24407000000 | G29: -30976000000 | I29: =A29 -> Purchase of Investments | J29: =B29 -> -109689000000 | K29: =C29 -> -76923000000 | L29: =D29 -> -29513000000 | M29: =E29 -> -48656000000 | N29: =F29 -> -24407000000 | O29: =G29 -> -30976000000
A30: Sale of Investments | B30: 106870000000 | C30: 67363000000 | D30: 45514000000 | E30: 62346000000 | F30: 53797000000 | G30: 44672000000 | I30: =A30 -> Sale of Investments | J30: =B30 -> 106870000000 | K30: =C30 -> 67363000000 | L30: =D30 -> 45514000000 | M30: =E30 -> 62346000000 | N30: =F30 -> 53797000000
A31: Other Investing Cash Flow | B31: -608000000 | C31: -1780000000 | D31: -1337000000 | E31: -1308000000 | F31: -1480000000 | G31: -1031000000 | I31: -Maturities of Marketable Securities | J31: 59023000000 | K31: 29917000000 | L31: 39686000000 | M31: 51211000000 | N31: 40907000000
A32: Purchase/Sale of Business, Net | B32: -33000000 | C32: -306000000 | I32: -Sales of Marketable Securities | J32: 47847000000 | K32: 37446000000 | L32: 5828000000 | M32: 11135000000 | N32: 12890000000
A33: Purchase/Acquisition of Business | B33: -33000000 | C33: -306000000 | I33: Reconcialiation Check | J33: =ABS(SUM(J31:J32))=ABS(J30) -> TRUE | K33: =ABS(SUM(K31:K32))=ABS(K30) -> TRUE | L33: =ABS(SUM(L31:L32))=ABS(L30) -> TRUE | M33: =ABS(SUM(M31:M32))=ABS(M30) -> TRUE | N33: =ABS(SUM(N31:N32))=ABS(N30) -> TRUE | P33: =AND(J33:O33) -> TRUE
A34: Purchase/Sale of Intangibles, Net | I34: =A31 -> Other Investing Cash Flow | J34: =B31 -> -608000000 | K34: =C31 -> -1780000000 | L34: =D31 -> -1337000000 | M34: =E31 -> -1308000000 | N34: =F31 -> -1480000000 | O34: =G34
A35: Purchase of Intangibles | I35: =A32 -> Purchase/Sale of Business, Net | J35: =B32 -> -33000000 | K35: =C32 -> -306000000 | L35: =D32 | M35: =E32 | N35: =F32 | O35: =G35
A36: Cash Flow from Financing Activities | B36: -93353000000 | C36: -110749000000 | D36: -108488000000 | E36: -121983000000 | F36: -120686000000 | G36: -120971000000 | I36: =A33 -> Purchase/Acquisition of Business | J36: =B33 -> -33000000 | K36: =C33 -> -306000000 | L36: =D33 | M36: =E33 | N36: =F33 | O36: =G36 -> -120971000000
A37: Cash Flow from Continuing Financing Activities | B37: -93353000000 | C37: -110749000000 | D37: -108488000000 | E37: -121983000000 | F37: -120686000000 | G37: -120971000000 | I37: =A34 -> Purchase/Sale of Intangibles, Net | J37: =B34 | K37: =C34 | L37: =D34 | M37: =E34 | N37: =F34 | O37: =G37 -> -120971000000
A38: Issuance of/Payments for Common Stock, Net | B38: -84866000000 | C38: -89402000000 | D38: -77550000000 | E38: -94949000000 | F38: -90711000000 | G38: -91806000000 | I38: =A35 -> Purchase of Intangibles | J38: =B35 | K38: =C35 | L38: =D35 | M38: =E35 | N38: =F35 | O38: =G38 -> -91806000000
A39: Payments for Common Stock | B39: -85971000000 | C39: -89402000000 | D39: -77550000000 | E39: -94949000000 | F39: -90711000000 | G39: -91806000000 | I39: =A36 -> Cash Flow from Financing Activities | J39: =B36 -> -93353000000 | K39: =C36 -> -110749000000 | L39: =D36 -> -108488000000 | M39: =E36 -> -121983000000 | N39: =F36 -> -120686000000 | O39: =G39 -> -91806000000
A40: Proceeds from Issuance of Common Stock | B40: 1105000000 | I40: =A37 -> Cash Flow from Continuing Financing Activities | J40: =B37 -> -93353000000 | K40: =C37 -> -110749000000 | L40: =D37 -> -108488000000 | M40: =E37 -> -121983000000 | N40: =F37 -> -120686000000 | O40: =G40
...

Sheet Balance Sheet
B1: Balance Sheet | I1: CHECK | J1: =AND(L59) -> TRUE
B2: Historical Financial Analysis | All figures in USD ($millions) | Inputs in Blue
B4: USD ($millions) | C4: FY2021 | D4: FY2022 | E4: FY2023 | F4: FY2024 | G4: FY2025 | H4: ="FY"&(MID(G4,3,4)+1) -> FY2026 | I4: ="FY"&(MID(H4,3,4)+1) -> FY2027 | J4: ="FY"&(MID(I4,3,4)+1) -> FY2028 | K4: ="FY"&(MID(J4,3,4)+1) -> FY2029 | L4: ="FY"&(MID(K4,3,4)+1) -> FY2030
B6: ASSETS
B7: Current Assets | H7: ="PROJECTED " & B7 -> PROJECTED Current Assets
B8: Cash & Cash Equivalents | C8: ='Raw (Balance Sheet)'!J6 -> 34940000000 | D8: ='Raw (Balance Sheet)'!K6 -> 23646000000 | E8: ='Raw (Balance Sheet)'!L6 -> 29965000000 | F8: ='Raw (Balance Sheet)'!M6 -> 29943000000 | G8: ='Raw (Balance Sheet)'!N6 -> 35934000000 | H8: ='Cash Flow Statement'!H49 -> 6.0850289e+10 | I8: ='Cash Flow Statement'!I49 -> 1.0476213e+11 | J8: ='Cash Flow Statement'!J49 -> 1.6865428e+11 | K8: ='Cash Flow Statement'!K49 -> 2.4946139e+11 | L8: ='Cash Flow Statement'!L49 -> 3.5118634e+11
B9: Short-Term Investments | C9: ='Raw (Balance Sheet)'!J9 -> 27699000000 | D9: ='Raw (Balance Sheet)'!K9 -> 24658000000 | E9: ='Raw (Balance Sheet)'!L9 -> 31590000000 | F9: ='Raw (Balance Sheet)'!M9 -> 35228000000 | G9: ='Raw (Balance Sheet)'!N9 -> 18763000000 | H9: 18763000000 | I9: 18763000000 | J9: 18763000000 | K9: 18763000000 | L9: 18763000000
