Workbook

Sheet Cover
B3: Startup ABC
B6: Startup Model
B10: Ticker: | C10: Startup ABC
B11: Sector: | C11: Sector ABC
B12: Funding Stage: | C12: Stage ABC
B13: Country: | C13: Malaysia
B14: Model Version: | C14: v1.0
B15: Prepared By: | C15: Bryan Brkat
B16: Date: | C16: 46102
B17: Currency: | C17: MYR/RM
B18: Deal Type: | C18: Equity / Convertible / SAFE
B20: MODEL STRUCTURE
B21: =HYPERLINK("#'Assumptions'!A4","Assumptions") -> Assumptions | C21: Read table B49 for colour legends reference and use L5 for product tier keyswitch
B22: =HYPERLINK("#'Financials (Annual)'!A4","Financials (Annual)") -> Financials (Annual) | C22: 2 year future projections for Income and Cash Flow
B23: =HYPERLINK("#'Revenue (Monthly)'!A4","Revenue (Monthly)") -> Revenue (Monthly) | C23: Alternative Revenue calculation via pricing tiers
B24: =HYPERLINK("#'Cohort Analysis (Y2026)'!A4","Cohort Analysis (Y2026)") -> Cohort Analysis (Y2026) | C24: Cohort analysis on Y2026 for CAC and LTV
B25: =HYPERLINK("#'Valuation'!A4","Valuation") -> Valuation | C25: DCF, multiples, VC method & scorecard
B26: =HYPERLINK("#'Return Modelling'!A4","Return Modelling") -> Return Modelling | C26: Entry/exit returns, IRR, MOIC, waterfall
B27: =HYPERLINK("#'Credit & Risk'!A4","Credit & Risk") -> Credit & Risk | C27: Risk scorecard & sensitivity analysis
B28: =HYPERLINK("#'Deal Structuring'!A4","Deal Structuring") -> Deal Structuring | C28: Term sheet economics & dilution model
B29: =HYPERLINK("#'Market Sizing'!A4","Market Sizing") -> Market Sizing | C29: TAM/SAM/SOM build-up
B30: =HYPERLINK("#'Competitive'!A4","Competitive") -> Competitive | C30: Competitor matrix & positioning
B31: =HYPERLINK("#'Deal Assessment'!A4","Deal Assessment") -> Deal Assessment | C31: Qualitative diligence scorecard

Sheet Assumptions
B1: KEY MODEL ASSUMPTIONS
B3: ASSUMPTION | E3: FY2024 | F3: FY2025 | G3: FY2026 | H3: FY2027 | I3: FY2028
B4: REVENUE ASSUMPTIONS | K4: Financial Model | L4: KeySwitch
B5: Revenue Year 1 | E5: 15000 | K5: Split product by tier level? | L5: 1
B6: Revenue Growth Rate | F6: 0.4 | G6: 0.4 | H6: 0.4 | I6: 0.4
B7: Gross Margin | E7: =1-E11 -> 0.6 | F7: =1-F11 -> 0.65 | G7: =1-G11 -> 0.67 | H7: =1-H11 -> 0.7 | I7: =1-I11 -> 0.7
B8: % Revenue from SaaS/Recurring
B10: COST & OPEX ASSUMPTIONS
B11: COGS as % of Revenue (if not using GM) | E11: 0.4 | F11: 0.35 | G11: 0.33 | H11: 0.3 | I11: 0.3
B12: R&D Expense as % of Revenue | E12: 0.2 | F12: 0.2 | G12: 0.2 | H12: 0.2 | I12: 0.2
B13: Sales & Marketing as % of Revenue | E13: 0.15 | F13: 0.15 | G13: 0.15 | H13: 0.15 | I13: 0.2
B14: G&A as % of Revenue | E14: 0.12 | F14: 0.12 | G14: 0.12 | H14: 0.12 | I14: 0.12
B15: D&A as % of Revenue | E15: 0.03 | F15: 0.03 | G15: 0.03 | H15: 0.03 | I15: 0.03
B16: Tax Rate (effective) | E16: 0.15 | F16: 0.15 | G16: 0.15 | H16: 0.15 | I16: 0.15
B18: WORKING CAPITAL & CAPEX
B19: Days Sales Outstanding (DSO) | E19: 45 | F19: 40 | G19: 45 | H19: 40 | I19: 30
B20: Days Payable Outstanding (DPO) | E20: 30 | F20: 20 | G20: 30 | H20: 20 | I20: 30
B21: Capex as % of Revenue | E21: 0.05 | F21: 0.05 | G21: 0.05 | H21: 0.05 | I21: 0.05
B23: FUNDING & CAPITAL STRUCTURE
B24: Investment Amount | G24: 50000
B25: Conversion Discount (%) | G25: 0.2
B26: Valuation Cap | G26: 15000
B27: Option Pool (% post-money) | G27: 0.1
B29: EXIT ASSUMPTIONS
B30: Exit Year (from investment) | G30: 5
B31: Exit Revenue Multiple (EV/Rev) | G31: 5
B32: Exit EBITDA Multiple (EV/EBITDA) | G32: 15
B33: Probability of Successful Exit | G33: 0.6
B34: Liquidation Preference (x) | G34: 1
B36: DCF & WACC ASSUMPTIONS
B37: Risk-Free Rate | G37: 0.043
B38: Equity Risk Premium (%) | C38: *Use 20% for high risk | G38: 0.2
B39: Beta | G39: 1.25
B40: Cost of Equity – CAPM (%) | G40: =G37+G39*G38 -> 0.293
B41: Pre-Tax Cost of Debt (%) | G41: 0.15
B42: Marginal Tax Rate (%) | G42: 0.21
B43: After-Tax Cost of Debt (%) | G43: =G41*(1-G42) -> 0.1185
B44: Equity Weight (%) | G44: 0.94
B45: Debt Weight (%) | G45: 0.06
B46: WACC (%) | G46: =G40*G44+G43*G45 -> 0.28253
...

Sheet Financials (Annual)
B1: FINANCIAL PROJECTIONS — BASE CASE
C3: FY2024 | D3: FY2025 | E3: FY2026 | F3: FY2027 | G3: FY2028
B4: INCOME STATEMENT
B5: Revenue | C5: =Assumptions!E5 -> 15000 | D5: =C5*(1+Assumptions!F6) -> 21000 | E5: =IF(Assumptions!L5=1,SUM('Revenue (Monthly)'!D56:O56),D5*(1+Assumptions!G6)) -> 31386.658 | F5: =IF(Assumptions!L5=1,SUM('Revenue (Monthly)'!P56:AA56),E5*(1+Assumptions!H6)) -> 45815.338 | G5: =F5*(1+Assumptions!I6) -> 64141.473
B6: YoY Growth | D6: =(D5-C5)/C5 -> 0.4 | E6: =(E5-D5)/D5 -> 0.49460274 | F6: =(F5-E5)/E5 -> 0.45970745 | G6: =(G5-F5)/F5 -> 0.4
B7: Gross Profit | C7: =C$5*Assumptions!E7 -> 9000 | D7: =D$5*Assumptions!F7 -> 13650 | E7: =E$5*Assumptions!G7 -> 21029.061 | F7: =F$5*Assumptions!H7 -> 32070.737 | G7: =G$5*Assumptions!I7 -> 44899.031
B8: Gross Margin % | C8: =C7/C5 -> 0.6 | D8: =D7/D5 -> 0.65 | E8: =E7/E5 -> 0.67 | F8: =F7/F5 -> 0.7 | G8: =G7/G5 -> 0.7
B9: R&D Expense | C9: =C5*Assumptions!E12 -> 3000 | D9: =D5*Assumptions!F12 -> 4200 | E9: =E5*Assumptions!G12 -> 6277.3315 | F9: =F5*Assumptions!H12 -> 9163.0676 | G9: =G5*Assumptions!I12 -> 12828.295
B10: Sales & Marketing Expense | C10: =C5*Assumptions!E13 -> 2250 | D10: =D5*Assumptions!F13 -> 3150 | E10: =E5*Assumptions!G13 -> 4707.9986 | F10: =F5*Assumptions!H13 -> 6872.3007 | G10: =G5*Assumptions!I13 -> 12828.295
B11: G&A Expense | C11: =C5*Assumptions!E14 -> 1800 | D11: =D5*Assumptions!F14 -> 2520 | E11: =E5*Assumptions!G14 -> 3766.3989 | F11: =F5*Assumptions!H14 -> 5497.8406 | G11: =G5*Assumptions!I14 -> 7696.9768
B12: Total OpEx | C12: =SUM(C9:C11) -> 7050 | D12: =SUM(D9:D11) -> 9870 | E12: =SUM(E9:E11) -> 14751.729 | F12: =SUM(F9:F11) -> 21533.209 | G12: =SUM(G9:G11) -> 33353.566
B13: EBITDA | C13: =C7-C12 -> 1950 | D13: =D7-D12 -> 3780 | E13: =E7-E12 -> 6277.3315 | F13: =F7-F12 -> 10537.528 | G13: =G7-G12 -> 11545.465
B14: EBITDA Margin % | C14: =C13/C5 -> 0.13 | D14: =D13/D5 -> 0.18 | E14: =E13/E5 -> 0.2 | F14: =F13/F5 -> 0.23 | G14: =G13/G5 -> 0.18
B16: D&A | C16: =C5*Assumptions!E15 -> 450 | D16: =D5*Assumptions!F15 -> 630 | E16: =E5*Assumptions!G15 -> 941.59973 | F16: =F5*Assumptions!H15 -> 1374.4601 | G16: =G5*Assumptions!I15 -> 1924.2442
B17: EBIT | C17: =C13-C16 -> 1500 | D17: =D13-D16 -> 3150 | E17: =E13-E16 -> 5335.7318 | F17: =F13-F16 -> 9163.0676 | G17: =G13-G16 -> 9621.221
B18: Tax | C18: =MAX(C17*Assumptions!E16,0) -> 225 | D18: =MAX(D17*Assumptions!F16,0) -> 472.5 | E18: =MAX(E17*Assumptions!G16,0) -> 800.35977 | F18: =MAX(F17*Assumptions!H16,0) -> 1374.4601 | G18: =MAX(G17*Assumptions!I16,0) -> 1443.1831
B19: Net Income / (Loss) | C19: =C17-C18 -> 1275 | D19: =D17-D18 -> 2677.5 | E19: =E17-E18 -> 4535.372 | F19: =F17-F18 -> 7788.6075 | G19: =G17-G18 -> 8178.0378
B21: CASH FLOW SUMMARY
B22: Net Income | C22: =C19 -> 1275 | D22: =D19 -> 2677.5 | E22: =E19 -> 4535.372 | F22: =F19 -> 7788.6075 | G22: =G19 -> 8178.0378
B23: Add: D&A | C23: =C16 -> 450 | D23: =D16 -> 630 | E23: =E16 -> 941.59973 | F23: =F16 -> 1374.4601 | G23: =G16 -> 1924.2442
B24: Change in Working Capital | D24: =D5/365*((Assumptions!F19-Assumptions!E19)-(Assumptions!F20-Assumptions!E20)) -> 287.67123 | E24: =E5/365*((Assumptions!G19-Assumptions!F19)-(Assumptions!G20-Assumptions!F20)) -> -429.95421 | F24: =F5/365*((Assumptions!H19-Assumptions!G19)-(Assumptions!H20-Assumptions!G20)) -> 627.60737 | G24: =G5/365*((Assumptions!I19-Assumptions!H19)-(Assumptions!I20-Assumptions!H20)) -> -3514.6013
B25: Capex | C25: =-C5*Assumptions!E21 -> -750 | D25: =-D5*Assumptions!F21 -> -1050 | E25: =-E5*Assumptions!G21 -> -1569.3329 | F25: =-F5*Assumptions!H21 -> -2290.7669 | G25: =-G5*Assumptions!I21 -> -3207.0737
B26: Free Cash Flow | C26: =C22+C23-C24+C25 -> 975 | D26: =D22+D23-D24+D25 -> 1969.8288 | E26: =E22+E23-E24+E25 -> 4337.5931 | F26: =F22+F23-F24+F25 -> 6244.6933 | G26: =G22+G23-G24+G25 -> 10409.81
B27: FCF Margin % | C27: =C26/C5 -> 0.065 | D27: =D26/D5 -> 0.09380137 | E27: =E26/E5 -> 0.13819863 | F27: =F26/F5 -> 0.13630137 | G27: =G26/G5 -> 0.16229452
B29: RULE OF 40 ANALYSIS
B30: Metric | C30: FY2024 | D30: FY2025 | E30: FY2026 | F30: FY2027 | G30: FY2028
B31: Annual Revenue Growth (%) | D31: =D6 -> 0.4 | E31: =E6 -> 0.49460274 | F31: =F6 -> 0.45970745 | G31: =G6 -> 0.4
B32: FCF Margin (%) [used in Rule of 40] | C32: =C27 -> 0.065 | D32: =D27 -> 0.09380137 | E32: =E27 -> 0.13819863 | F32: =F27 -> 0.13630137 | G32: =G27 -> 0.16229452
B33: EBITDA Margin (%) [reference only] | C33: =C14 -> 0.13 | D33: =D14 -> 0.18 | E33: =E14 -> 0.2 | F33: =F14 -> 0.23 | G33: =G14 -> 0.18
B34: RULE OF 40 SCORE (Growth % + FCF Margin %) | D34: =IF(D5=0,"",(D31+D32)*100) -> 49.380137 | E34: =IF(E5=0,"",(E31+E32)*100) -> 63.280137 | F34: =IF(F5=0,"",(F31+F32)*100) -> 59.600882 | G34: =IF(G5=0,"",(G31+G32)*100) -> 56.229452
B35: Interpretation (≥40 = Healthy, ≥60 = Excellent) | C35: ="N/A" -> N/A | D35: =IF(D34=0,"N/A",IF(D34>=60,"✅ Excellent",IF(D34>=40,"✅ Healthy",IF(D34>=20,"🔶 Developing","⚠️ Below Target")))) -> ✅ Healthy | E35: =IF(E34=0,"N/A",IF(E34>=60,"✅ Excellent",IF(E34>=40,"✅ Healthy",IF(E34>=20,"🔶 Developing","⚠️ Below Target")))) -> ✅ Excellent | F35: =IF(F34=0,"N/A",IF(F34>=60,"✅ Excellent",IF(F34>=40,"✅ Healthy",IF(F34>=20,"🔶 Developing","⚠️ Below Target")))) -> ✅ Healthy | G35: =IF(G34=0,"N/A",IF(G34>=60,"✅ Excellent",IF(G34>=40,"✅ Healthy",IF(G34>=20,"🔶 Developing","⚠️ Below Target")))) -> ✅ Healthy

Sheet Revenue (Monthly)
B1: MRR-ARR RECURRING REVENUE MODEL | 24-Month Rolling Waterfall
B3: A. PRICING TIER ASSUMPTIONS (Blue = input)
B4: Tier | C4: ARPU / Month (MYR) | D4: Monthly Churn % | E4: Expansion Rate % | F4: Contraction Rate % | G4: Colour
B5: Basic | C5: 5 | D5: =0.4/12 -> 0.033333333 | E5: 0.1 | F5: 0
B6: Standard | C6: 10 | D6: =0.4/12 -> 0.033333333 | E6: 0.1 | F6: 0.05
B7: Premium | C7: 20 | D7: =0.4/12 -> 0.033333333 | E7: 0 | F7: 0.07
B9: B. MONTHLY NEW SUBSCRIBER ACQUISITIONS (inputs — change per month as needed)
B10: Tier | C10: Yr 1 Monthly Avg | D10: Y2026 (M1) | E10: Y2026 (M2) | F10: Y2026 (M3) | G10: Y2026 (M4) | H10: Y2026 (M5) | I10: Y2026 (M6) | J10: Y2026 (M7) | K10: Y2026 (M8) | L10: Y2026 (M9) | M10: Y2026 (M10) | N10: Y2026 (M11) | O10: Y2026 (M12) | P10: Y2027 (M1) | Q10: Y2027 (M2) | R10: Y2027 (M3) | S10: Y2027 (M4) | T10: Y2027 (M5) | U10: Y2027 (M6) | V10: Y2027 (M7) | W10: Y2027 (M8) | X10: Y2027 (M9) | Y10: Y2027 (M10) | Z10: Y2027 (M11) | AA10: Y2027 (M12)
B11: New Subs — Basic | C11: =AVERAGE(D11:O11) -> 5.9028554 | D11: =0.5/12*D17 -> 8.3333333 | E11: =0.5/12*E17 -> 7.6805556 | F11: =0.5/12*F17 -> 7.1255787 | G11: =0.5/12*G17 -> 6.6308111 | H11: =0.5/12*H17 -> 6.1987616 | I11: =0.5/12*I17 -> 5.8320433 | J11: =0.5/12*J17 -> 5.4917118 | K11: =0.5/12*K17 -> 5.2205331 | ... AA11: =0.5/12*AA17 -> 3.1060358
B12: New Subs — Standard | C12: =AVERAGE(D12:O12) -> 3.7676279 | D12: =0.5/12*D28 -> 2.0833333 | E12: =0.5/12*E28 -> 2.6284722 | F12: =0.5/12*F28 -> 3.1129919 | G12: =0.5/12*G28 -> 3.4926999 | H12: =0.5/12*H28 -> 3.7632291 | I12: =0.5/12*I28 -> 3.9616969 | J12: =0.5/12*J28 -> 4.085101 | K12: =0.5/12*K28 -> 4.2136468 | ... AA12: =0.5/12*AA28 -> 4.6629144
B13: New Subs — Premium | C13: =AVERAGE(D13:O13) -> 2.0895447 | D13: =0.5/12*D39 -> 0.83333333 | E13: =0.5/12*E39 -> 0.99305556 | F13: =0.5/12*F39 -> 1.1594329 | G13: =0.5/12*G39 -> 1.3744092 | H13: =0.5/12*H39 -> 1.6400096 | I13: =0.5/12*I39 -> 1.9166767 | J13: =0.5/12*J39 -> 2.2048716 | K13: =0.5/12*K39 -> 2.4634079 | ... AA13: =0.5/12*AA39 -> 5.6155335
B15: C1. SUBSCRIBER WATERFALL — BASIC TIER
B16: Metric | C16: Yr 1 Monthly Avg | D16: Y2026 (M1) | E16: Y2026 (M2) | F16: Y2026 (M3) | G16: Y2026 (M4) | H16: Y2026 (M5) | I16: Y2026 (M6) | J16: Y2026 (M7) | K16: Y2026 (M8) | L16: Y2026 (M9) | M16: Y2026 (M10) | N16: Y2026 (M11) | O16: Y2026 (M12) | P16: Y2027 (M1) | Q16: Y2027 (M2) | R16: Y2027 (M3) | S16: Y2027 (M4) | T16: Y2027 (M5) | U16: Y2027 (M6) | V16: Y2027 (M7) | W16: Y2027 (M8) | X16: Y2027 (M9) | Y16: Y2027 (M10) | Z16: Y2027 (M11) | AA16: Y2027 (M12)
B17: Starting Subs | C17: =AVERAGE(D17:O17) -> 141.66853 | D17: 200 | E17: =D22 -> 184.33333 | F17: =E22 -> 171.01389 | G17: =F22 -> 159.13947 | H17: =G22 -> 148.77028 | I17: =H22 -> 139.96904 | J17: =I22 -> 131.80108 | K17: =J22 -> 125.2928 | L17: =K22 -> 118.51333 | ... AA17: =Z22 -> 74.54486
B18: New Subs | C18: =AVERAGE(D18:O18) -> 5.9028554 | D18: =D11 -> 8.3333333 | E18: =E11 -> 7.6805556 | F18: =F11 -> 7.1255787 | G18: =G11 -> 6.6308111 | H18: =H11 -> 6.1987616 | I18: =I11 -> 5.8320433 | J18: =J11 -> 5.4917118 | K18: =K11 -> 5.2205331 | ... AA18: =AA11 -> 3.1060358
B19: Churned Subs | C19: =AVERAGE(D19:O19) -> -4.75 | D19: =-ROUND(D17*$D$5,0) -> -7 | E19: =-ROUND(E17*$D$5,0) -> -6 | F19: =-ROUND(F17*$D$5,0) -> -6 | G19: =-ROUND(G17*$D$5,0) -> -5 | H19: =-ROUND(H17*$D$5,0) -> -5 | I19: =-ROUND(I17*$D$5,0) -> -5 | J19: =-ROUND(J17*$D$5,0) -> -4 | K19: =-ROUND(K17*$D$5,0) -> -4 | ... AA19: =-ROUND(AA17*$D$5,0) -> -2
B20: Expanded (Upgrades IN) | C20: =AVERAGE(D20:O20) -> 14.166667 | D20: =ROUND(D17*$E$5,0) -> 20 | E20: =ROUND(E17*$E$5,0) -> 18 | F20: =ROUND(F17*$E$5,0) -> 17 | G20: =ROUND(G17*$E$5,0) -> 16 | H20: =ROUND(H17*$E$5,0) -> 15 | I20: =ROUND(I17*$E$5,0) -> 14 | J20: =ROUND(J17*$E$5,0) -> 13 | K20: =ROUND(K17*$E$5,0) -> 13 | ... AA20: =ROUND(AA17*$E$5,0) -> 7
B21: Contracted (Downgrades OUT) | C21: =AVERAGE(D21:O21) -> 0 | D21: =-ROUND(D17*$F$5,0) -> 0 | E21: =-ROUND(E17*$F$5,0) -> 0 | F21: =-ROUND(F17*$F$5,0) -> 0 | G21: =-ROUND(G17*$F$5,0) -> 0 | H21: =-ROUND(H17*$F$5,0) -> 0 | I21: =-ROUND(I17*$F$5,0) -> 0 | J21: =-ROUND(J17*$F$5,0) -> 0 | K21: =-ROUND(K17*$F$5,0) -> 0 | ... AA21: =-ROUND(AA17*$F$5,0) -> 0
B22: Ending Active Subs | C22: =AVERAGE(D22:O22) -> 133.15472 | D22: =MAX(D17+D18+D19-D20+D21-D32,0) -> 184.33333 | E22: =MAX(E17+E18+E19-E20+E21-E32,0) -> 171.01389 | F22: =MAX(F17+F18+F19-F20+F21-F32,0) -> 159.13947 | G22: =MAX(G17+G18+G19-G20+G21-G32,0) -> 148.77028 | H22: =MAX(H17+H18+H19-H20+H21-H32,0) -> 139.96904 | I22: =MAX(I17+I18+I19-I20+I21-I32,0) -> 131.80108 | J22: =MAX(J17+J18+J19-J20+J21-J32,0) -> 125.2928 | K22: =MAX(K17+K18+K19-K20+K21-K32,0) -> 118.51333 | ... AA22: =MAX(AA17+AA18+AA19-AA20+AA21-AA32,0) -> 74.650895
B23: ARPU (MYR) | C23: =AVERAGE(D23:O23) -> 5 | D23: =$C$5 -> 5 | E23: =$C$5 -> 5 | F23: =$C$5 -> 5 | G23: =$C$5 -> 5 | H23: =$C$5 -> 5 | I23: =$C$5 -> 5 | J23: =$C$5 -> 5 | K23: =$C$5 -> 5 | ... AA23: =$C$5 -> 5
B24: Tier MRR | C24: =AVERAGE(D24:O24) -> 708.34265 | D24: =D17*D23 -> 1000 | E24: =E17*E23 -> 921.66667 | F24: =F17*F23 -> 855.06944 | G24: =G17*G23 -> 795.69734 | H24: =H17*H23 -> 743.85139 | I24: =I17*I23 -> 699.8452 | J24: =J17*J23 -> 659.00542 | K24: =K17*K23 -> 626.46398 | ... AA24: =AA17*AA23 -> 372.7243
B26: C2. SUBSCRIBER WATERFALL — STANDARD TIER
B27: Metric | C27: Yr 1 Monthly Avg | D27: Y2026 (M1) | E27: Y2026 (M2) | F27: Y2026 (M3) | G27: Y2026 (M4) | H27: Y2026 (M5) | I27: Y2026 (M6) | J27: Y2026 (M7) | K27: Y2026 (M8) | L27: Y2026 (M9) | M27: Y2026 (M10) | N27: Y2026 (M11) | O27: Y2026 (M12) | P27: Y2027 (M1) | Q27: Y2027 (M2) | R27: Y2027 (M3) | S27: Y2027 (M4) | T27: Y2027 (M5) | U27: Y2027 (M6) | V27: Y2027 (M7) | W27: Y2027 (M8) | X27: Y2027 (M9) | Y27: Y2027 (M10) | Z27: Y2027 (M11) | AA27: Y2027 (M12)
B28: Starting Subs | C28: =AVERAGE(D28:O28) -> 90.423068 | D28: 50 | E28: =D33 -> 63.083333 | F28: =E33 -> 74.711806 | G28: =F33 -> 83.824797 | H28: =G33 -> 90.317497 | I28: =H33 -> 95.080726 | J28: =I33 -> 98.042423 | K28: =J33 -> 101.12752 | L28: =K33 -> 104.34117 | ... AA28: =Z33 -> 111.90995
B29: New Subs | C29: =AVERAGE(D29:O29) -> 3.7676279 | D29: =D12 -> 2.0833333 | E29: =E12 -> 2.6284722 | F29: =F12 -> 3.1129919 | G29: =G12 -> 3.4926999 | H29: =H12 -> 3.7632291 | I29: =I12 -> 3.9616969 | J29: =J12 -> 4.085101 | K29: =K12 -> 4.2136468 | ... AA29: =AA12 -> 4.6629144
B30: Churned Subs | C30: =AVERAGE(D30:O30) -> -3 | D30: =-ROUND(D28*$D$6,0) -> -2 | E30: =-ROUND(E28*$D$6,0) -> -2 | F30: =-ROUND(F28*$D$6,0) -> -2 | G30: =-ROUND(G28*$D$6,0) -> -3 | H30: =-ROUND(H28*$D$6,0) -> -3 | I30: =-ROUND(I28*$D$6,0) -> -3 | J30: =-ROUND(J28*$D$6,0) -> -3 | K30: =-ROUND(K28*$D$6,0) -> -3 | ... AA30: =-ROUND(AA28*$D$6,0) -> -4
B31: Expanded (Upgrades IN) | C31: =AVERAGE(D31:O31) -> 9 | D31: =ROUND(D28*$E$6,0) -> 5 | E31: =ROUND(E28*$E$6,0) -> 6 | F31: =ROUND(F28*$E$6,0) -> 7 | G31: =ROUND(G28*$E$6,0) -> 8 | H31: =ROUND(H28*$E$6,0) -> 9 | I31: =ROUND(I28*$E$6,0) -> 10 | J31: =ROUND(J28*$E$6,0) -> 10 | K31: =ROUND(K28*$E$6,0) -> 10 | ... AA31: =ROUND(AA28*$E$6,0) -> 11
B32: Contracted (Downgrades OUT) | C32: =AVERAGE(D32:O32) -> -4.5 | D32: =-ROUND(D28*$F$6,0) -> -3 | E32: =-ROUND(E28*$F$6,0) -> -3 | F32: =-ROUND(F28*$F$6,0) -> -4 | G32: =-ROUND(G28*$F$6,0) -> -4 | H32: =-ROUND(H28*$F$6,0) -> -5 | I32: =-ROUND(I28*$F$6,0) -> -5 | J32: =-ROUND(J28*$F$6,0) -> -5 | K32: =-ROUND(K28*$F$6,0) -> -5 | ... AA32: =-ROUND(AA28*$F$6,0) -> -6
B33: Ending Active Subs | C33: =AVERAGE(D33:O33) -> 95.357363 | D33: =MAX(D28+D29+D30+D20-D31+D32-D43,0) -> 63.083333 | E33: =MAX(E28+E29+E30+E20-E31+E32-E43,0) -> 74.711806 | F33: =MAX(F28+F29+F30+F20-F31+F32-F43,0) -> 83.824797 | G33: =MAX(G28+G29+G30+G20-G31+G32-G43,0) -> 90.317497 | H33: =MAX(H28+H29+H30+H20-H31+H32-H43,0) -> 95.080726 | I33: =MAX(I28+I29+I30+I20-I31+I32-I43,0) -> 98.042423 | J33: =MAX(J28+J29+J30+J20-J31+J32-J43,0) -> 101.12752 | K33: =MAX(K28+K29+K30+K20-K31+K32-K43,0) -> 104.34117 | ... AA33: =MAX(AA28+AA29+AA30+AA20-AA31+AA32-AA43,0) -> 111.57286
B34: ARPU (MYR) | C34: =AVERAGE(D34:O34) -> 10 | D34: =$C$6 -> 10 | E34: =$C$6 -> 10 | F34: =$C$6 -> 10 | G34: =$C$6 -> 10 | H34: =$C$6 -> 10 | I34: =$C$6 -> 10 | J34: =$C$6 -> 10 | K34: =$C$6 -> 10 | ... AA34: =$C$6 -> 10
B35: Tier MRR | C35: =AVERAGE(D35:O35) -> 904.23068 | D35: =D28*D34 -> 500 | E35: =E28*E34 -> 630.83333 | F35: =F28*F34 -> 747.11806 | G35: =G28*G34 -> 838.24797 | H35: =H28*H34 -> 903.17497 | I35: =I28*I34 -> 950.80726 | J35: =J28*J34 -> 980.42423 | K35: =K28*K34 -> 1011.2752 | ... AA35: =AA28*AA34 -> 1119.0995
B37: C3. SUBSCRIBER WATERFALL — PREMIUM TIER
B38: Metric | C38: Yr 1 Monthly Avg | D38: Y2026 (M1) | E38: Y2026 (M2) | F38: Y2026 (M3) | G38: Y2026 (M4) | H38: Y2026 (M5) | I38: Y2026 (M6) | J38: Y2026 (M7) | K38: Y2026 (M8) | L38: Y2026 (M9) | M38: Y2026 (M10) | N38: Y2026 (M11) | O38: Y2026 (M12) | P38: Y2027 (M1) | Q38: Y2027 (M2) | R38: Y2027 (M3) | S38: Y2027 (M4) | T38: Y2027 (M5) | U38: Y2027 (M6) | V38: Y2027 (M7) | W38: Y2027 (M8) | X38: Y2027 (M9) | Y38: Y2027 (M10) | Z38: Y2027 (M11) | AA38: Y2027 (M12)
B39: Starting Subs | C39: =AVERAGE(D39:O39) -> 50.149073 | D39: 20 | E39: =D44 -> 23.833333 | F39: =E44 -> 27.826389 | G39: =F44 -> 32.985822 | H39: =G44 -> 39.360231 | I39: =H44 -> 46.000241 | J39: =I44 -> 52.916917 | K39: =J44 -> 59.121789 | L39: =K44 -> 65.585197 | ... AA39: =Z44 -> 134.7728
B40: New Subs | C40: =AVERAGE(D40:O40) -> 2.0895447 | D40: =D13 -> 0.83333333 | E40: =E13 -> 0.99305556 | F40: =F13 -> 1.1594329 | G40: =G13 -> 1.3744092 | H40: =H13 -> 1.6400096 | I40: =I13 -> 1.9166767 | J40: =J13 -> 2.2048716 | K40: =K13 -> 2.4634079 | ... AA40: =AA13 -> 5.6155335
B41: Churned Subs | C41: =AVERAGE(D41:O41) -> -1.75 | D41: =-ROUND(D39*$D$7,0) -> -1 | E41: =-ROUND(E39*$D$7,0) -> -1 | F41: =-ROUND(F39*$D$7,0) -> -1 | G41: =-ROUND(G39*$D$7,0) -> -1 | H41: =-ROUND(H39*$D$7,0) -> -1 | I41: =-ROUND(I39*$D$7,0) -> -2 | J41: =-ROUND(J39*$D$7,0) -> -2 | K41: =-ROUND(K39*$D$7,0) -> -2 | ... AA41: =-ROUND(AA39*$D$7,0) -> -4
B42: Expanded (Upgrades IN) | C42: =AVERAGE(D42:O42) -> 0 | D42: =ROUND(D39*$E$7,0) -> 0 | E42: =ROUND(E39*$E$7,0) -> 0 | F42: =ROUND(F39*$E$7,0) -> 0 | G42: =ROUND(G39*$E$7,0) -> 0 | H42: =ROUND(H39*$E$7,0) -> 0 | I42: =ROUND(I39*$E$7,0) -> 0 | J42: =ROUND(J39*$E$7,0) -> 0 | K42: =ROUND(K39*$E$7,0) -> 0 | ... AA42: =ROUND(AA39*$E$7,0) -> 0
B43: Contracted (Downgrades OUT) | C43: =AVERAGE(D43:O43) -> -3.5 | D43: =-ROUND(D39*$F$7,0) -> -1 | E43: =-ROUND(E39*$F$7,0) -> -2 | F43: =-ROUND(F39*$F$7,0) -> -2 | G43: =-ROUND(G39*$F$7,0) -> -2 | H43: =-ROUND(H39*$F$7,0) -> -3 | I43: =-ROUND(I39*$F$7,0) -> -3 | J43: =-ROUND(J39*$F$7,0) -> -4 | K43: =-ROUND(K39*$F$7,0) -> -4 | ... AA43: =-ROUND(AA39*$F$7,0) -> -9
B44: Ending Active Subs | C44: =AVERAGE(D44:O44) -> 55.988618 | D44: =MAX(D39+D40+D41+D42+D31+D43,0) -> 23.833333 | E44: =MAX(E39+E40+E41+E42+E31+E43,0) -> 27.826389 | F44: =MAX(F39+F40+F41+F42+F31+F43,0) -> 32.985822 | G44: =MAX(G39+G40+G41+G42+G31+G43,0) -> 39.360231 | H44: =MAX(H39+H40+H41+H42+H31+H43,0) -> 46.000241 | I44: =MAX(I39+I40+I41+I42+I31+I43,0) -> 52.916917 | J44: =MAX(J39+J40+J41+J42+J31+J43,0) -> 59.121789 | K44: =MAX(K39+K40+K41+K42+K31+K43,0) -> 65.585197 | ... AA44: =MAX(AA39+AA40+AA41+AA42+AA31+AA43,0) -> 138.38834
B45: ARPU (MYR) | C45: =AVERAGE(D45:O45) -> 20 | D45: =$C$7 -> 20 | E45: =$C$7 -> 20 | F45: =$C$7 -> 20 | G45: =$C$7 -> 20 | H45: =$C$7 -> 20 | I45: =$C$7 -> 20 | J45: =$C$7 -> 20 | K45: =$C$7 -> 20 | ... AA45: =$C$7 -> 20
...

Sheet Cohort Analysis (Y2026)
B1: COHORT ANALYSIS | Customer Retention, CAC, LTV & Cash Burn
B3: A. COHORT ASSUMPTIONS & INPUTS
B4: Parameter | C4: Value | D4: Notes
B5: Blended ARPU (MYR/month) | C5: ='Revenue (Monthly)'!C11/SUM('Revenue (Monthly)'!C11:C13)*'Revenue (Monthly)'!C5+'Revenue (Monthly)'!C12/SUM('Revenue (Monthly)'!C11:C13)*'Revenue (Monthly)'!C6+'Revenue (Monthly)'!C13/SUM('Revenue (Monthly)'!C11:C13)*'Revenue (Monthly)'!C7 -> 9.2671081 | D5: Average across all tiers
B6: Blended Gross Margin % | C6: ='Financials (Annual)'!E8 -> 0.67 | D6: From Fin. Projections assumptions
B7: Blended Monthly Churn Rate | C7: ='Revenue (Monthly)'!C11/SUM('Revenue (Monthly)'!C11:C13)*'Revenue (Monthly)'!D5+'Revenue (Monthly)'!C12/SUM('Revenue (Monthly)'!C11:C13)*'Revenue (Monthly)'!D6+'Revenue (Monthly)'!C13/SUM('Revenue (Monthly)'!C11:C13)*'Revenue (Monthly)'!D7 -> 0.033333333 | D7: Blended across tiers
B8: Monthly Sales & Mktg Cost | C8: ='Revenue (Monthly)'!C56*Assumptions!G13 -> 410.86794 | D8: Total S&M spend / month
B9: Monthly Opex Excl. S&M | C9: ='Revenue (Monthly)'!C56*(Assumptions!G12+Assumptions!G14) -> 876.51827 | D9: R&D + G&A + Other monthly
B10: Discount Rate (monthly) | C10: =0.2/12 -> 0.016666667 | D10: (eg. 20% annual / 12)
B12: B. NEW CUSTOMERS ACQUIRED PER COHORT MONTH (inputs)
B13: Cohort (Signup Month) | C13: New Customers Acq. | D13: S&M Spend
B14: Month 1 | C14: ='Revenue (Monthly)'!$C$11/SUM('Revenue (Monthly)'!$C$11:$C$13)*'Revenue (Monthly)'!D11+'Revenue (Monthly)'!$C$12/SUM('Revenue (Monthly)'!$C$11:$C$13)*'Revenue (Monthly)'!D12+'Revenue (Monthly)'!$C$13/SUM('Revenue (Monthly)'!$C$11:$C$13)*'Revenue (Monthly)'!D13 -> 4.9983702 | D14: =$C$8 -> 410.86794
B15: Month 2 | C15: ='Revenue (Monthly)'!$C$11/SUM('Revenue (Monthly)'!$C$11:$C$13)*'Revenue (Monthly)'!E11+'Revenue (Monthly)'!$C$12/SUM('Revenue (Monthly)'!$C$11:$C$13)*'Revenue (Monthly)'!E12+'Revenue (Monthly)'!$C$13/SUM('Revenue (Monthly)'!$C$11:$C$13)*'Revenue (Monthly)'!E13 -> 4.8737425 | D15: =$C$8 -> 410.86794
B16: Month 3 | C16: ='Revenue (Monthly)'!$C$11/SUM('Revenue (Monthly)'!$C$11:$C$13)*'Revenue (Monthly)'!F11+'Revenue (Monthly)'!$C$12/SUM('Revenue (Monthly)'!$C$11:$C$13)*'Revenue (Monthly)'!F12+'Revenue (Monthly)'!$C$13/SUM('Revenue (Monthly)'!$C$11:$C$13)*'Revenue (Monthly)'!F13 -> 4.7799667 | D16: =$C$8 -> 410.86794
B17: Month 4 | C17: ='Revenue (Monthly)'!$C$11/SUM('Revenue (Monthly)'!$C$11:$C$13)*'Revenue (Monthly)'!G11+'Revenue (Monthly)'!$C$12/SUM('Revenue (Monthly)'!$C$11:$C$13)*'Revenue (Monthly)'!G12+'Revenue (Monthly)'!$C$13/SUM('Revenue (Monthly)'!$C$11:$C$13)*'Revenue (Monthly)'!G13 -> 4.6914686 | D17: =$C$8 -> 410.86794
B18: Month 5 | C18: ='Revenue (Monthly)'!$C$11/SUM('Revenue (Monthly)'!$C$11:$C$13)*'Revenue (Monthly)'!H11+'Revenue (Monthly)'!$C$12/SUM('Revenue (Monthly)'!$C$11:$C$13)*'Revenue (Monthly)'!H12+'Revenue (Monthly)'!$C$13/SUM('Revenue (Monthly)'!$C$11:$C$13)*'Revenue (Monthly)'!H13 -> 4.6084681 | D18: =$C$8 -> 410.86794
B19: Month 6 | C19: ='Revenue (Monthly)'!$C$11/SUM('Revenue (Monthly)'!$C$11:$C$13)*'Revenue (Monthly)'!I11+'Revenue (Monthly)'!$C$12/SUM('Revenue (Monthly)'!$C$11:$C$13)*'Revenue (Monthly)'!I12+'Revenue (Monthly)'!$C$13/SUM('Revenue (Monthly)'!$C$11:$C$13)*'Revenue (Monthly)'!I13 -> 4.5371397 | D19: =$C$8 -> 410.86794
B20: Month 7 | C20: ='Revenue (Monthly)'!$C$11/SUM('Revenue (Monthly)'!$C$11:$C$13)*'Revenue (Monthly)'!J11+'Revenue (Monthly)'!$C$12/SUM('Revenue (Monthly)'!$C$11:$C$13)*'Revenue (Monthly)'!J12+'Revenue (Monthly)'!$C$13/SUM('Revenue (Monthly)'!$C$11:$C$13)*'Revenue (Monthly)'!J13 -> 4.4570556 | D20: =$C$8 -> 410.86794
B21: Month 8 | C21: ='Revenue (Monthly)'!$C$11/SUM('Revenue (Monthly)'!$C$11:$C$13)*'Revenue (Monthly)'!K11+'Revenue (Monthly)'!$C$12/SUM('Revenue (Monthly)'!$C$11:$C$13)*'Revenue (Monthly)'!K12+'Revenue (Monthly)'!$C$13/SUM('Revenue (Monthly)'!$C$11:$C$13)*'Revenue (Monthly)'!K13 -> 4.4080598 | D21: =$C$8 -> 410.86794
B22: Month 9 | C22: ='Revenue (Monthly)'!$C$11/SUM('Revenue (Monthly)'!$C$11:$C$13)*'Revenue (Monthly)'!L11+'Revenue (Monthly)'!$C$12/SUM('Revenue (Monthly)'!$C$11:$C$13)*'Revenue (Monthly)'!L12+'Revenue (Monthly)'!$C$13/SUM('Revenue (Monthly)'!$C$11:$C$13)*'Revenue (Monthly)'!L13 -> 4.3570225 | D22: =$C$8 -> 410.86794
B23: Month 10 | C23: ='Revenue (Monthly)'!$C$11/SUM('Revenue (Monthly)'!$C$11:$C$13)*'Revenue (Monthly)'!M11+'Revenue (Monthly)'!$C$12/SUM('Revenue (Monthly)'!$C$11:$C$13)*'Revenue (Monthly)'!M12+'Revenue (Monthly)'!$C$13/SUM('Revenue (Monthly)'!$C$11:$C$13)*'Revenue (Monthly)'!M13 -> 4.3173694 | D23: =$C$8 -> 410.86794
B24: Month 11 | C24: ='Revenue (Monthly)'!$C$11/SUM('Revenue (Monthly)'!$C$11:$C$13)*'Revenue (Monthly)'!N11+'Revenue (Monthly)'!$C$12/SUM('Revenue (Monthly)'!$C$11:$C$13)*'Revenue (Monthly)'!N12+'Revenue (Monthly)'!$C$13/SUM('Revenue (Monthly)'!$C$11:$C$13)*'Revenue (Monthly)'!N13 -> 4.2643349 | D24: =$C$8 -> 410.86794
B25: Month 12 | C25: ='Revenue (Monthly)'!$C$11/SUM('Revenue (Monthly)'!$C$11:$C$13)*'Revenue (Monthly)'!O11+'Revenue (Monthly)'!$C$12/SUM('Revenue (Monthly)'!$C$11:$C$13)*'Revenue (Monthly)'!O12+'Revenue (Monthly)'!$C$13/SUM('Revenue (Monthly)'!$C$11:$C$13)*'Revenue (Monthly)'!O13 -> 4.2016872 | D25: =$C$8 -> 410.86794
B27: C. COHORT RETENTION TABLE (% of original cohort still active)
B28: Cohort → Months Since Acquisition: | C28: Cohort Size | D28: Month 0 (Acq) | E28: M+0 | F28: Y2026 (M1) | G28: Y2026 (M2) | H28: Y2026 (M3) | I28: Y2026 (M4) | J28: Y2026 (M5) | K28: Y2026 (M6) | L28: Y2026 (M7) | M28: Y2026 (M8) | N28: Y2026 (M9) | O28: Y2026 (M10) | P28: Y2026 (M11) | Q28: Y2026 (M12)
B29: Month 1 | C29: =C14 -> 4.9983702 | D29: 1 | E29: 1 | F29: =(1-$C$7)^1 -> 0.96666667 | G29: =(1-$C$7)^2 -> 0.93444444 | H29: =(1-$C$7)^3 -> 0.9032963 | I29: =(1-$C$7)^4 -> 0.87318642 | J29: =(1-$C$7)^5 -> 0.84408021 | K29: =(1-$C$7)^6 -> 0.8159442 | L29: =(1-$C$7)^7 -> 0.78874606 | M29: =(1-$C$7)^8 -> 0.76245452 | N29: =(1-$C$7)^9 -> 0.73703937 | O29: =(1-$C$7)^10 -> 0.71247139 | P29: =(1-$C$7)^11 -> 0.68872235 | Q29: =(1-$C$7)^12 -> 0.66576494
B30: Month 2 | C30: =C15 -> 4.8737425 | D30: 1 | E30: 1 | F30: =(1-$C$7)^1 -> 0.96666667 | G30: =(1-$C$7)^2 -> 0.93444444 | H30: =(1-$C$7)^3 -> 0.9032963 | I30: =(1-$C$7)^4 -> 0.87318642 | J30: =(1-$C$7)^5 -> 0.84408021 | K30: =(1-$C$7)^6 -> 0.8159442 | L30: =(1-$C$7)^7 -> 0.78874606 | M30: =(1-$C$7)^8 -> 0.76245452 | N30: =(1-$C$7)^9 -> 0.73703937 | O30: =(1-$C$7)^10 -> 0.71247139 | P30: =(1-$C$7)^11 -> 0.68872235 | Q30: =(1-$C$7)^12 -> 0.66576494
B31: Month 3 | C31: =C16 -> 4.7799667 | D31: 1 | E31: 1 | F31: =(1-$C$7)^1 -> 0.96666667 | G31: =(1-$C$7)^2 -> 0.93444444 | H31: =(1-$C$7)^3 -> 0.9032963 | I31: =(1-$C$7)^4 -> 0.87318642 | J31: =(1-$C$7)^5 -> 0.84408021 | K31: =(1-$C$7)^6 -> 0.8159442 | L31: =(1-$C$7)^7 -> 0.78874606 | M31: =(1-$C$7)^8 -> 0.76245452 | N31: =(1-$C$7)^9 -> 0.73703937 | O31: =(1-$C$7)^10 -> 0.71247139 | P31: =(1-$C$7)^11 -> 0.68872235 | Q31: =(1-$C$7)^12 -> 0.66576494
B32: Month 4 | C32: =C17 -> 4.6914686 | D32: 1 | E32: 1 | F32: =(1-$C$7)^1 -> 0.96666667 | G32: =(1-$C$7)^2 -> 0.93444444 | H32: =(1-$C$7)^3 -> 0.9032963 | I32: =(1-$C$7)^4 -> 0.87318642 | J32: =(1-$C$7)^5 -> 0.84408021 | K32: =(1-$C$7)^6 -> 0.8159442 | L32: =(1-$C$7)^7 -> 0.78874606 | M32: =(1-$C$7)^8 -> 0.76245452 | N32: =(1-$C$7)^9 -> 0.73703937 | O32: =(1-$C$7)^10 -> 0.71247139 | P32: =(1-$C$7)^11 -> 0.68872235 | Q32: =(1-$C$7)^12 -> 0.66576494
B33: Month 5 | C33: =C18 -> 4.6084681 | D33: 1 | E33: 1 | F33: =(1-$C$7)^1 -> 0.96666667 | G33: =(1-$C$7)^2 -> 0.93444444 | H33: =(1-$C$7)^3 -> 0.9032963 | I33: =(1-$C$7)^4 -> 0.87318642 | J33: =(1-$C$7)^5 -> 0.84408021 | K33: =(1-$C$7)^6 -> 0.8159442 | L33: =(1-$C$7)^7 -> 0.78874606 | M33: =(1-$C$7)^8 -> 0.76245452 | N33: =(1-$C$7)^9 -> 0.73703937 | O33: =(1-$C$7)^10 -> 0.71247139 | P33: =(1-$C$7)^11 -> 0.68872235 | Q33: =(1-$C$7)^12 -> 0.66576494
B34: Month 6 | C34: =C19 -> 4.5371397 | D34: 1 | E34: 1 | F34: =(1-$C$7)^1 -> 0.96666667 | G34: =(1-$C$7)^2 -> 0.93444444 | H34: =(1-$C$7)^3 -> 0.9032963 | I34: =(1-$C$7)^4 -> 0.87318642 | J34: =(1-$C$7)^5 -> 0.84408021 | K34: =(1-$C$7)^6 -> 0.8159442 | L34: =(1-$C$7)^7 -> 0.78874606 | M34: =(1-$C$7)^8 -> 0.76245452 | N34: =(1-$C$7)^9 -> 0.73703937 | O34: =(1-$C$7)^10 -> 0.71247139 | P34: =(1-$C$7)^11 -> 0.68872235 | Q34: =(1-$C$7)^12 -> 0.66576494
B35: Month 7 | C35: =C20 -> 4.4570556 | D35: 1 | E35: 1 | F35: =(1-$C$7)^1 -> 0.96666667 | G35: =(1-$C$7)^2 -> 0.93444444 | H35: =(1-$C$7)^3 -> 0.9032963 | I35: =(1-$C$7)^4 -> 0.87318642 | J35: =(1-$C$7)^5 -> 0.84408021 | K35: =(1-$C$7)^6 -> 0.8159442 | L35: =(1-$C$7)^7 -> 0.78874606 | M35: =(1-$C$7)^8 -> 0.76245452 | N35: =(1-$C$7)^9 -> 0.73703937 | O35: =(1-$C$7)^10 -> 0.71247139 | P35: =(1-$C$7)^11 -> 0.68872235 | Q35: =(1-$C$7)^12 -> 0.66576494
B36: Month 8 | C36: =C21 -> 4.4080598 | D36: 1 | E36: 1 | F36: =(1-$C$7)^1 -> 0.96666667 | G36: =(1-$C$7)^2 -> 0.93444444 | H36: =(1-$C$7)^3 -> 0.9032963 | I36: =(1-$C$7)^4 -> 0.87318642 | J36: =(1-$C$7)^5 -> 0.84408021 | K36: =(1-$C$7)^6 -> 0.8159442 | L36: =(1-$C$7)^7 -> 0.78874606 | M36: =(1-$C$7)^8 -> 0.76245452 | N36: =(1-$C$7)^9 -> 0.73703937 | O36: =(1-$C$7)^10 -> 0.71247139 | P36: =(1-$C$7)^11 -> 0.68872235 | Q36: =(1-$C$7)^12 -> 0.66576494
B37: Month 9 | C37: =C22 -> 4.3570225 | D37: 1 | E37: 1 | F37: =(1-$C$7)^1 -> 0.96666667 | G37: =(1-$C$7)^2 -> 0.93444444 | H37: =(1-$C$7)^3 -> 0.9032963 | I37: =(1-$C$7)^4 -> 0.87318642 | J37: =(1-$C$7)^5 -> 0.84408021 | K37: =(1-$C$7)^6 -> 0.8159442 | L37: =(1-$C$7)^7 -> 0.78874606 | M37: =(1-$C$7)^8 -> 0.76245452 | N37: =(1-$C$7)^9 -> 0.73703937 | O37: =(1-$C$7)^10 -> 0.71247139 | P37: =(1-$C$7)^11 -> 0.68872235 | Q37: =(1-$C$7)^12 -> 0.66576494
B38: Month 10 | C38: =C23 -> 4.3173694 | D38: 1 | E38: 1 | F38: =(1-$C$7)^1 -> 0.96666667 | G38: =(1-$C$7)^2 -> 0.93444444 | H38: =(1-$C$7)^3 -> 0.9032963 | I38: =(1-$C$7)^4 -> 0.87318642 | J38: =(1-$C$7)^5 -> 0.84408021 | K38: =(1-$C$7)^6 -> 0.8159442 | L38: =(1-$C$7)^7 -> 0.78874606 | M38: =(1-$C$7)^8 -> 0.76245452 | N38: =(1-$C$7)^9 -> 0.73703937 | O38: =(1-$C$7)^10 -> 0.71247139 | P38: =(1-$C$7)^11 -> 0.68872235 | Q38: =(1-$C$7)^12 -> 0.66576494
B39: Month 11 | C39: =C24 -> 4.2643349 | D39: 1 | E39: 1 | F39: =(1-$C$7)^1 -> 0.96666667 | G39: =(1-$C$7)^2 -> 0.93444444 | H39: =(1-$C$7)^3 -> 0.9032963 | I39: =(1-$C$7)^4 -> 0.87318642 | J39: =(1-$C$7)^5 -> 0.84408021 | K39: =(1-$C$7)^6 -> 0.8159442 | L39: =(1-$C$7)^7 -> 0.78874606 | M39: =(1-$C$7)^8 -> 0.76245452 | N39: =(1-$C$7)^9 -> 0.73703937 | O39: =(1-$C$7)^10 -> 0.71247139 | P39: =(1-$C$7)^11 -> 0.68872235 | Q39: =(1-$C$7)^12 -> 0.66576494
B40: Month 12 | C40: =C25 -> 4.2016872 | D40: 1 | E40: 1 | F40: =(1-$C$7)^1 -> 0.96666667 | G40: =(1-$C$7)^2 -> 0.93444444 | H40: =(1-$C$7)^3 -> 0.9032963 | I40: =(1-$C$7)^4 -> 0.87318642 | J40: =(1-$C$7)^5 -> 0.84408021 | K40: =(1-$C$7)^6 -> 0.8159442 | L40: =(1-$C$7)^7 -> 0.78874606 | M40: =(1-$C$7)^8 -> 0.76245452 | N40: =(1-$C$7)^9 -> 0.73703937 | O40: =(1-$C$7)^10 -> 0.71247139 | P40: =(1-$C$7)^11 -> 0.68872235 | Q40: =(1-$C$7)^12 -> 0.66576494
B42: D. CUMULATIVE REVENUE PER COHORT (MYR 000s)
B43: Cohort | C43: Cohort Size | D43: Total 12M Rev | E43: M+0 | F43: Y2026 (M1) | G43: Y2026 (M2) | H43: Y2026 (M3) | I43: Y2026 (M4) | J43: Y2026 (M5) | K43: Y2026 (M6) | L43: Y2026 (M7) | M43: Y2026 (M8) | N43: Y2026 (M9) | O43: Y2026 (M10) | P43: Y2026 (M11) | Q43: Y2026 (M12)
B44: Month 1 | C44: =C14 -> 4.9983702 | D44: =SUM(E44,F44,G44,H44,I44,J44,K44,L44,M44,N44,O44,P44) -> 464.45743 | E44: =$C14*E29*$C$5 -> 46.320437 | F44: =$C14*F29*$C$5 -> 44.776422 | G44: =$C14*G29*$C$5 -> 43.283875 | H44: =$C14*H29*$C$5 -> 41.841079 | I44: =$C14*I29*$C$5 -> 40.446376 | J44: =$C14*J29*$C$5 -> 39.098164 | K44: =$C14*K29*$C$5 -> 37.794892 | L44: =$C14*L29*$C$5 -> 36.535062 | ... Q44: =$C14*Q29*$C$5 -> 30.838523
...

Sheet Valuation
B1: STARTUP VALUATION FRAMEWORK
B3: METHOD 1: DISCOUNTED CASH FLOW (DCF)
B4: Item
B5: WACC | C5: =Assumptions!G46 -> 0.28253
B6: Terminal Growth Rate | C6: =Assumptions!G47 -> 0.03
B7: Terminal Year FCF | C7: ='Financials (Annual)'!F26 -> 6244.6933
B8: Terminal Value | C8: =C7/(C5-C6) -> 24728.521
B9: PV of FCFs (Y1-Y5) | C9: =IFERROR(NPV(C5,'Financials (Annual)'!C26:G26),0) -> 9321.7909
B10: PV of Terminal Value | C10: =C8/(1+C5)^5 -> 7126.2405
B11: Enterprise Value (DCF) | C11: =C9+C10 -> 16448.031
B13: METHOD 2: REVENUE MULTIPLES
B14: Item
B15: LTM / Forward Revenue | C15: ='Financials (Annual)'!F5 -> 45815.338
B16: Revenue Multiple (EV/Rev) | C16: =Assumptions!G31 -> 5
B17: Implied EV | C17: =C15*C16 -> 229076.69
B18: EBITDA Multiple (EV/EBITDA) | C18: =Assumptions!G32 -> 15
B19: LTM EBITDA | C19: ='Financials (Annual)'!F13 -> 10537.528
B20: Implied EV (EBITDA method) | C20: =C18*C19 -> 158062.92
B21: Blended EV (50/50) | C21: =(C17+C20)/2 -> 193569.8
B23: METHOD 3: VC METHOD (FORWARD RETURNS)
B24: Item
B25: Latest Revenue | C25: ='Financials (Annual)'!F5 -> 45815.338
B26: Revenue Multiple | C26: =Assumptions!G31 -> 5
B27: Current Value | C27: =C25*C26 -> 229076.69
B28: Target Return (MOIC) | C28: 5
B29: Investment Amount | C29: =Assumptions!G24 -> 50000
B30: Required Exit Value | C30: =C32*C28 -> 1395383.5
B31: Pre-money Valuation (VC implied) | C31: =C27 -> 229076.69
B32: Post-money Valuation | C32: =C31+C29 -> 279076.69
B33: Ownership % Required | C33: =C29/C32 -> 0.17916222
B35: VALUATION SUMMARY — IMPLIED EV RANGE
B36: Method | C36: Value | D36: Weight | E36: Wtd. EV
B37: DCF | C37: =C11 -> 16448.031 | D37: 0.3 | E37: =C37*D37 -> 4934.4094
B38: Revenue Multiples | C38: =C21 -> 193569.8 | D38: 0.4 | E38: =C38*D38 -> 77427.921
B39: VC Method | C39: =C27 -> 229076.69 | D39: 0.3 | E39: =C39*D39 -> 68723.007
B40: BLENDED VALUATION | E40: =SUM(E37:E39) -> 151085.34

Sheet Return Modelling
B1: RETURN MODELLING — IRR / MOIC / EXIT WATERFALL
B3: ENTRY ECONOMICS
B4: Item
B5: Pre-money Valuation | C5: =Valuation!C31 -> 229076.69
B6: Investment Amount | C6: =Assumptions!G24 -> 50000
B7: Post-money Valuation | C7: =C5+C6 -> 279076.69
B8: Ownership % (entry) | C8: =Valuation!C33 -> 0.17916222
B9: Option Pool Dilution | C9: =Assumptions!G27 -> 0.1
B10: Diluted Ownership % | C10: =C8*(1-C9) -> 0.161246
B12: EXIT ECONOMICS & RETURNS
B13: Item
B14: Required Exit Value | C14: =Valuation!C30 -> 1395383.5
B15: Holding Period (years) | C15: =Assumptions!G30 -> 5
B16: Liquidation Preference | C16: =C6*Assumptions!G34 -> 50000
B17: Proceeds to Investor | C17: =MAX(C16,C14*C10) -> 225000
B18: MOIC (Gross) | C18: =IFERROR(C17/C6,0) -> 4.5
B19: IRR (Gross) | C19: =IFERROR((C18)^(1/C15)-1,0) -> 0.35096004
B20: Prob-weighted MOIC | C20: =C18*Assumptions!G33 -> 2.7
B22: IRR SENSITIVITY: HOLDING PERIOD vs EXIT MULTIPLE
B23: Holding Period ↓ Exit Multiple → | C23: 3.0x | D23: 5.0x | E23: 8.0x | F23: 10.0x | G23: 15.0x
B24: 3 Years
B25: 4 Years
B26: 5 Years
B27: 6 Years
B28: 7 Years

Sheet Credit & Risk
B1: CREDIT & RISK ASSESSMENT SCORECARD
B3: RISK SCORECARD (Score 1–5: 1=Very High Risk, 5=Very Low Risk)
B4: Risk Factor | C4: Description | D4: Score (1–5) | E4: Weight | F4: Wtd. Score | G4: Flag
B5: Management Team Quality | C5: Founders' domain expertise, execution track record, & team depth | D5: 5 | E5: 0.15 | F5: =D5*E5 -> 0.75 | G5: =IF(D5<=2,"⚠️ HIGH RISK",IF(D5<=3,"🔶 MODERATE RISK","✅ LOW RISK")) -> ✅ LOW RISK
B6: Market Size & Growth | C6: TAM/SAM size, growth trajectory, and timing of entry | D6: 4 | E6: 0.1 | F6: =D6*E6 -> 0.4 | G6: =IF(D6<=2,"⚠️ HIGH RISK",IF(D6<=3,"🔶 MODERATE RISK","✅ LOW RISK")) -> ✅ LOW RISK
B7: Business Model Viability | C7: Revenue model clarity, unit economics, and path to profitability | D7: 3 | E7: 0.12 | F7: =D7*E7 -> 0.36 | G7: =IF(D7<=2,"⚠️ HIGH RISK",IF(D7<=3,"🔶 MODERATE RISK","✅ LOW RISK")) -> 🔶 MODERATE RISK
B8: Product / Technology Moat | C8: IP defensibility, switching costs, and competitive differentiation | D8: 3 | E8: 0.12 | F8: =D8*E8 -> 0.36 | G8: =IF(D8<=2,"⚠️ HIGH RISK",IF(D8<=3,"🔶 MODERATE RISK","✅ LOW RISK")) -> 🔶 MODERATE RISK
B9: Traction & Validation | C9: Revenue growth, customer retention, and pilot/POC outcomes | D9: 2 | E9: 0.1 | F9: =D9*E9 -> 0.2 | G9: =IF(D9<=2,"⚠️ HIGH RISK",IF(D9<=3,"🔶 MODERATE RISK","✅ LOW RISK")) -> ⚠️ HIGH RISK
B10: Regulatory & Compliance | C10: Licensing requirements, regulatory exposure, and legal risk | D10: 2 | E10: 0.08 | F10: =D10*E10 -> 0.16 | G10: =IF(D10<=2,"⚠️ HIGH RISK",IF(D10<=3,"🔶 MODERATE RISK","✅ LOW RISK")) -> ⚠️ HIGH RISK
B11: Financial Health | C11: Burn rate, runway, cash management, and fundraising history | D11: 2 | E11: 0.08 | F11: =D11*E11 -> 0.16 | G11: =IF(D11<=2,"⚠️ HIGH RISK",IF(D11<=3,"🔶 MODERATE RISK","✅ LOW RISK")) -> ⚠️ HIGH RISK
B12: Exit Likelihood | C12: Probability of M&A, IPO, or strategic exit within 5–7 years | D12: 4 | E12: 0.08 | F12: =D12*E12 -> 0.32 | G12: =IF(D12<=2,"⚠️ HIGH RISK",IF(D12<=3,"🔶 MODERATE RISK","✅ LOW RISK")) -> ✅ LOW RISK
B13: Macro / Country Risk | C13: Political stability, currency risk, and market development | D13: 3 | E13: 0.07 | F13: =D13*E13 -> 0.21 | G13: =IF(D13<=2,"⚠️ HIGH RISK",IF(D13<=3,"🔶 MODERATE RISK","✅ LOW RISK")) -> 🔶 MODERATE RISK
B14: ESG & Governance | C14: Environmental, social, governance practices and board quality | D14: 3 | E14: 0.1 | F14: =D14*E14 -> 0.3 | G14: =IF(D14<=2,"⚠️ HIGH RISK",IF(D14<=3,"🔶 MODERATE RISK","✅ LOW RISK")) -> 🔶 MODERATE RISK
B15: TOTAL WEIGHTED RISK SCORE (Max = 5.0) | F15: =SUM(F5:F14) -> 3.22 | G15: =IF(F15<2,"❌ DO NOT INVEST",IF(F15<3,"⚠️ HIGH CAUTION",IF(F15<4,"🔶 PROCEED WITH CONDITIONS","✅ FAVOURABLE"))) -> 🔶 PROCEED WITH CONDITIONS
B17: MOIC SENSITIVITY: REVENUE GROWTH vs EXIT MULTIPLE
B18: MOIC → Revenue Growth → | C18: 30% | D18: 50% | E18: 75% | F18: 100% | G18: 150%
B19: 3.0x Exit
B20: 5.0x Exit
B21: 8.0x Exit
B22: 10.0x Exit
B23: 15.0x Exit

Sheet Deal Structuring
B1: DEAL STRUCTURING & TERM SHEET ECONOMICS
B3: CAP TABLE — PRE & POST INVESTMENT
B4: Shareholder | C4: Pre-$ Shares | D4: Pre-$ % | E4: Post-$ Shares | F4: Post-$ %
B5: Founders | C5: 150000 | D5: =C5/$C$9 -> 0.75 | E5: 150000 | F5: =E5/$E$9 -> 0.6
B6: Existing Investors | C6: 25000 | D6: =C6/$C$9 -> 0.125 | E6: 25000 | F6: =E6/$E$9 -> 0.1
B7: ESOP / Option Pool | C7: 25000 | D7: =C7/$C$9 -> 0.125 | E7: 25000 | F7: =E7/$E$9 -> 0.1
B8: New Investor | C8: 0 | D8: =C8/$C$9 -> 0 | E8: =Assumptions!G24 -> 50000 | F8: =E8/$E$9 -> 0.2
B9: Total | C9: =SUM(C5:C8) -> 200000 | D9: =SUM(D5:D8) -> 1 | E9: =SUM(E5:E8) -> 250000 | F9: =SUM(F5:F8) -> 1
B11: TERM SHEET KEY TERMS CHECKLIST
B12: Term | C12: Proposed | D12: Negotiated | E12: Status | F12: Notes
B13: Investment Instrument | C13: Ordinary Equity | E13: Pending
B14: Pre-money Valuation | C14: ='Return Modelling'!C5 -> 229076.69 | E14: Accepted
B15: Investment Size | C15: ='Return Modelling'!C6 -> 50000 | E15: Accepted
B16: Equity Stake | C16: ='Return Modelling'!C10 -> 0.161246 | E16: Accepted
B17: Board Seat | C17: 1 Observer seat | E17: Pending
B18: Anti-dilution | C18: Broad-based weighted avg | E18: Pending
B19: Pro-rata Rights | C19: Yes, for future rounds | E19: Pending
B20: Information Rights | C20: Quarterly financials | E20: Pending
B21: Liquidation Preference | C21: 1x non-participating | E21: Pending
B22: Drag-along | C22: Majority consent | E22: Pending
B23: Vesting Schedule | C23: 4yr / 1yr cliff (founders) | E23: Pending
B24: Use of Proceeds | C24: Product, Sales, Ops | E24: Pending

Sheet Market Sizing
B1: MARKET SIZING — TAM / SAM / SOM
B3: TOP-DOWN MARKET SIZING
B4: Market Layer | C4: Definition | D4: Current | E4: CAGR | F4: 2027E | G4: Method / Source
B5: TAM — Total Addressable Market | C5: Global market for the sector this company operates in | D5: 5000000 | E5: 0.15 | F5: =D5*(1+E5)^2 -> 6612500
B6: SAM — Serviceable Addressable | C6: Geographic & segment subset that the business model can realistically serve | D6: 500000 | E6: 0.2 | F6: =D6*(1+E6)^2 -> 720000
B7: SOM — Serviceable Obtainable | C7: Realistic market capture in 2 years given competition and execution | D7: 25000 | E7: 0.35 | F7: =D7*(1+E7)^2 -> 45562.5
B8: Company Revenue Projection (Y2027) | C8: Internal financial model projection | D8: ='Financials (Annual)'!F5 -> 45815.338 | E8: — | F8: —
B10: BOTTOM-UP VALIDATION
B11: Total Target Customers | C11: 10000
B12: Reachable Customers (Year 2) | C12: 10
B13: Average Revenue per Customer | C13: 50
B14: Implied Revenue | C14: =C11*C12*C13/1000 -> 5000
B15: Cross-check vs SOM | C15: =IFERROR(C14/F7,0) -> 0.10973937

Sheet Competitive
B1: COMPETITIVE LANDSCAPE MATRIX
B3: COMPETITOR BENCHMARKING
B4: Company | C4: Funding Stage | D4: Est. ARR | E4: Gross Margin | F4: Key Differentiator | G4: Key Weakness | H4: Threat Level (1–5)
B5: ★ Startup ABC | C5: Seed | D5: 500 | E5: 60% | F5: Enter differentiator | G5: Early stage, limited track record | H5: 5
B6: Competitor A | C6: Series A | D6: 2000 | E6: 55% | F6: Enter differentiator | G6: Enter weakness | H6: 4
B7: Competitor B | C7: Series B | D7: 8000 | E7: 50% | F7: Enter differentiator | G7: Enter weakness | H7: 3
B8: Competitor C | C8: Pre-IPO | D8: 25000 | E8: 45% | F8: Enter differentiator | G8: Enter weakness | H8: 2
B9: Incumbent / Corp. | C9: Listed | D9: 150000 | E9: 35% | F9: Distribution scale | G9: Slow innovation | H9: 1
B11: FEATURE COMPARISON MATRIX (Rate 1-5)
B12: Feature / Capability | C12: This Company | D12: Comp. A | E12: Comp. B | F12: Comp. C | G12: Incumbent
B13: Core Product / Platform | C13: 4 | D13: 4 | E13: 5 | F13: 4 | G13: 4
B14: Mobile / Digital-first UX | C14: 4 | D14: 4 | E14: 4 | F14: 4 | G14: 5
B15: AI / Data Analytics | C15: 4 | D15: 2 | E15: 4 | F15: 2 | G15: 4
B16: Regulatory / Compliance Feature | C16: 4 | D16: 3 | E16: 2 | F16: 4 | G16: 4
B17: Embedded Finance / Lending | C17: 4 | D17: 2 | E17: 4 | F17: 4 | G17: 5
B18: Marketplace / Network Effects | C18: 3 | D18: 3 | E18: 3 | F18: 3 | G18: 3
B19: Government / Institutional Ties | C19: 3 | D19: 3 | E19: 3 | F19: 2 | G19: 3
B20: ASEAN / Regional Scalability | C20: 3 | D20: 3 | E20: 3 | F20: 2 | G20: 3
B21: Total | C21: =SUM(C13:C20) -> 29 | D21: =SUM(D13:D20) -> 24 | E21: =SUM(E13:E20) -> 28 | F21: =SUM(F13:F20) -> 25 | G21: =SUM(G13:G20) -> 31

Sheet Deal Assessment
B1: DEAL ASSESSMENT — QUALITATIVE DILIGENCE SCORECARD
B3: TEAM & MANAGEMENT
B4: Diligence Item | C4: Score (1–5) | D4: Analyst Notes | E4: Evidence / Source | F4: Flag
B5: Founder domain expertise | C5: 3 | D5: Rate 1-5 and document evidence in notes column | F5: =IF(C5<=2,"⚠️ Flag",IF(C5<=3,"🔶 Review","✅ OK")) -> 🔶 Review
B6: Cofounder / team complementarity | C6: 3 | D6: Engineering + commercial + domain balance | F6: =IF(C6<=2,"⚠️ Flag",IF(C6<=3,"🔶 Review","✅ OK")) -> 🔶 Review
B7: Prior startup / exit experience | C7: 3 | D7: Relevant track record | F7: =IF(C7<=2,"⚠️ Flag",IF(C7<=3,"🔶 Review","✅ OK")) -> 🔶 Review
B8: Ability to attract talent | C8: 3 | D8: Glassdoor, LinkedIn growth, key hires | F8: =IF(C8<=2,"⚠️ Flag",IF(C8<=3,"🔶 Review","✅ OK")) -> 🔶 Review
B9: Board / advisor quality | C9: 3 | D9: Institutional, domain, and network value | F9: =IF(C9<=2,"⚠️ Flag",IF(C9<=3,"🔶 Review","✅ OK")) -> 🔶 Review
B10: SECTION AVERAGE — TEAM & MANAGEMENT | C10: =AVERAGE(C5:C9) -> 3
B12: PRODUCT & TECHNOLOGY
B13: Diligence Item | C13: Score (1–5) | D13: Analyst Notes | E13: Evidence / Source | F13: Flag
B14: Product-market fit evidence | C14: 3 | D14: NPS, churn, customer references | F14: =IF(C14<=2,"⚠️ Flag",IF(C14<=3,"🔶 Review","✅ OK")) -> 🔶 Review
B15: IP / defensibility | C15: 3 | D15: Patents, proprietary data, network effects | F15: =IF(C15<=2,"⚠️ Flag",IF(C15<=3,"🔶 Review","✅ OK")) -> 🔶 Review
B16: Product roadmap clarity | C16: 3 | D16: 18-month roadmap reviewed? | F16: =IF(C16<=2,"⚠️ Flag",IF(C16<=3,"🔶 Review","✅ OK")) -> 🔶 Review
B17: Tech stack scalability | C17: 3 | D17: Cloud-native, modular, security | F17: =IF(C17<=2,"⚠️ Flag",IF(C17<=3,"🔶 Review","✅ OK")) -> 🔶 Review
B18: SECTION AVERAGE — PRODUCT & TECHNOLOGY | C18: =AVERAGE(C14:C17) -> 3
B20: MARKET & TRACTION
B21: Diligence Item | C21: Score (1–5) | D21: Analyst Notes | E21: Evidence / Source | F21: Flag
B22: Revenue traction | C22: 3 | D22: MoM / YoY growth rate | F22: =IF(C22<=2,"⚠️ Flag",IF(C22<=3,"🔶 Review","✅ OK")) -> 🔶 Review
B23: Customer concentration risk | C23: 3 | D23: Top 3 customers as % of revenue | F23: =IF(C23<=2,"⚠️ Flag",IF(C23<=3,"🔶 Review","✅ OK")) -> 🔶 Review
B24: Sales pipeline quality | C24: 3 | D24: Qualified pipeline 3x quarterly target? | F24: =IF(C24<=2,"⚠️ Flag",IF(C24<=3,"🔶 Review","✅ OK")) -> 🔶 Review
B25: Unit economics (LTV:CAC) | C25: 3 | D25: Target: LTV/CAC > 3x | F25: =IF(C25<=2,"⚠️ Flag",IF(C25<=3,"🔶 Review","✅ OK")) -> 🔶 Review
B26: Churn / retention rates | C26: 3 | D26: Target: Net Revenue Retention > 100% | F26: =IF(C26<=2,"⚠️ Flag",IF(C26<=3,"🔶 Review","✅ OK")) -> 🔶 Review
B27: SECTION AVERAGE — MARKET & TRACTION | C27: =AVERAGE(C22:C26) -> 3
B29: FINANCIAL & GOVERNANCE
B30: Diligence Item | C30: Score (1–5) | D30: Analyst Notes | E30: Evidence / Source | F30: Flag
B31: Financial statements quality | C31: 3 | D31: Audited? Management accounts reviewed? | F31: =IF(C31<=2,"⚠️ Flag",IF(C31<=3,"🔶 Review","✅ OK")) -> 🔶 Review
B32: Burn rate & runway | C32: 3 | D32: Months of runway at current burn | F32: =IF(C32<=2,"⚠️ Flag",IF(C32<=3,"🔶 Review","✅ OK")) -> 🔶 Review
B33: Cap table cleanliness | C33: 3 | D33: No red flags: clean preferences, no 3rd-party liens | F33: =IF(C33<=2,"⚠️ Flag",IF(C33<=3,"🔶 Review","✅ OK")) -> 🔶 Review
B34: Corporate governance | C34: 3 | D34: Board minutes, shareholder agreements reviewed? | F34: =IF(C34<=2,"⚠️ Flag",IF(C34<=3,"🔶 Review","✅ OK")) -> 🔶 Review
B35: Use of proceeds clarity | C35: 3 | D35: Specific, measurable allocation of funds | F35: =IF(C35<=2,"⚠️ Flag",IF(C35<=3,"🔶 Review","✅ OK")) -> 🔶 Review
B36: SECTION AVERAGE — FINANCIAL & GOVERNANCE | C36: =AVERAGE(C31:C35) -> 3
B38: OVERALL DEAL RECOMMENDATION | F38: Enter recommendation here
